Workbook

Sheet Statistics
B1: Descriptive Statistics
B2: SD = sample standard deviation (STDEV); CV = SD / Mean × 100; Q1/Q3 = QUARTILE. Missing ratings are excluded from rating statistics.
B4: Group Type | C4: Comparison Group | D4: Brand | E4: Model | F4: Platform | G4: n | H4: Price Mean | I4: Price Median | J4: Price SD | K4: Price CV (%) | L4: Price Min | M4: Price Q1 | N4: Price Q3 | O4: Price Max | P4: Rating n | Q4: Rating Mean | R4: Rating Median | S4: Rating SD | T4: Rating CV (%) | U4: Rating Min | V4: Rating Q1 | W4: Rating Q3 | X4: Rating Max
B5: Overall | G5: =COUNT(All_Data!$F$3:$F$117) -> 115 | H5: =IF(G5=0,"",AVERAGE(All_Data!$F$3:$F$117)) -> 12061.36 | I5: =IF(G5=0,"",MEDIAN(All_Data!$F$3:$F$117)) -> 10900 | J5: =IF(G5<2,"",STDEV(All_Data!$F$3:$F$117)) -> 7460.9378 | K5: =IF(OR(G5<2,H5=0),"",J5/H5*100) -> 61.858183 | L5: =IF(G5=0,"",MIN(All_Data!$F$3:$F$117)) -> 429 | M5: =IF(G5=0,"",QUARTILE(All_Data!$F$3:$F$117,1)) -> 6650 | N5: =IF(G5=0,"",QUARTILE(All_Data!$F$3:$F$117,3)) -> 15999.5 | O5: =IF(G5=0,"",MAX(All_Data!$F$3:$F$117)) -> 34055 | P5: =COUNT(All_Data!$G$3:$G$117) -> 73 | Q5: =IF(P5=0,"",AVERAGE(All_Data!$G$3:$G$117)) -> 4.8479452 | R5: =IF(P5=0,"",MEDIAN(All_Data!$G$3:$G$117)) -> 5 | S5: =IF(P5<2,"",STDEV(All_Data!$G$3:$G$117)) -> 0.54188703 | T5: =IF(OR(P5<2,Q5=0),"",S5/Q5*100) -> 11.177664 | U5: =IF(P5=0,"",MIN(All_Data!$G$3:$G$117)) -> 1 | V5: =IF(P5=0,"",QUARTILE(All_Data!$G$3:$G$117,1)) -> 4.9 | W5: =IF(P5=0,"",QUARTILE(All_Data!$G$3:$G$117,3)) -> 5 | X5: =IF(P5=0,"",MAX(All_Data!$G$3:$G$117)) -> 5
B6: Brand | D6: Apple | G6: =COUNT(Apple!$F$3:$F$6) -> 4 | H6: =IF(G6=0,"",AVERAGE(Apple!$F$3:$F$6)) -> 20532.5 | I6: =IF(G6=0,"",MEDIAN(Apple!$F$3:$F$6)) -> 19515 | J6: =IF(G6<2,"",STDEV(Apple!$F$3:$F$6)) -> 4892.943 | K6: =IF(OR(G6<2,H6=0),"",J6/H6*100) -> 23.830235 | L6: =IF(G6=0,"",MIN(Apple!$F$3:$F$6)) -> 15900 | M6: =IF(G6=0,"",QUARTILE(Apple!$F$3:$F$6,1)) -> 17572.5 | N6: =IF(G6=0,"",QUARTILE(Apple!$F$3:$F$6,3)) -> 22475 | O6: =IF(G6=0,"",MAX(Apple!$F$3:$F$6)) -> 27200 | P6: =COUNT(Apple!$G$3:$G$6) -> 4 | Q6: =IF(P6=0,"",AVERAGE(Apple!$G$3:$G$6)) -> 4.95 | R6: =IF(P6=0,"",MEDIAN(Apple!$G$3:$G$6)) -> 5 | S6: =IF(P6<2,"",STDEV(Apple!$G$3:$G$6)) -> 0.1 | T6: =IF(OR(P6<2,Q6=0),"",S6/Q6*100) -> 2.020202 | U6: =IF(P6=0,"",MIN(Apple!$G$3:$G$6)) -> 4.8 | V6: =IF(P6=0,"",QUARTILE(Apple!$G$3:$G$6,1)) -> 4.95 | W6: =IF(P6=0,"",QUARTILE(Apple!$G$3:$G$6,3)) -> 5 | X6: =IF(P6=0,"",MAX(Apple!$G$3:$G$6)) -> 5
B7: Brand | D7: Samsung | G7: =COUNT(Samsung!$F$3:$F$98) -> 96 | H7: =IF(G7=0,"",AVERAGE(Samsung!$F$3:$F$98)) -> 12022.351 | I7: =IF(G7=0,"",MEDIAN(Samsung!$F$3:$F$98)) -> 10945 | J7: =IF(G7<2,"",STDEV(Samsung!$F$3:$F$98)) -> 7342.5649 | K7: =IF(OR(G7<2,H7=0),"",J7/H7*100) -> 61.074287 | L7: =IF(G7=0,"",MIN(Samsung!$F$3:$F$98)) -> 429 | M7: =IF(G7=0,"",QUARTILE(Samsung!$F$3:$F$98,1)) -> 6987.5 | N7: =IF(G7=0,"",QUARTILE(Samsung!$F$3:$F$98,3)) -> 15696 | O7: =IF(G7=0,"",MAX(Samsung!$F$3:$F$98)) -> 34055 | P7: =COUNT(Samsung!$G$3:$G$98) -> 60 | Q7: =IF(P7=0,"",AVERAGE(Samsung!$G$3:$G$98)) -> 4.8233333 | R7: =IF(P7=0,"",MEDIAN(Samsung!$G$3:$G$98)) -> 5 | S7: =IF(P7<2,"",STDEV(Samsung!$G$3:$G$98)) -> 0.59499798 | T7: =IF(OR(P7<2,Q7=0),"",S7/Q7*100) -> 12.335825 | U7: =IF(P7=0,"",MIN(Samsung!$G$3:$G$98)) -> 1 | V7: =IF(P7=0,"",QUARTILE(Samsung!$G$3:$G$98,1)) -> 4.9 | W7: =IF(P7=0,"",QUARTILE(Samsung!$G$3:$G$98,3)) -> 5 | X7: =IF(P7=0,"",MAX(Samsung!$G$3:$G$98)) -> 5
B8: Brand | D8: Huawei | G8: =COUNT(Huawei!$F$3:$F$17) -> 15 | H8: =IF(G8=0,"",AVERAGE(Huawei!$F$3:$F$17)) -> 10052.047 | I8: =IF(G8=0,"",MEDIAN(Huawei!$F$3:$F$17)) -> 4990 | J8: =IF(G8<2,"",STDEV(Huawei!$F$3:$F$17)) -> 7580.7479 | K8: =IF(OR(G8<2,H8=0),"",J8/H8*100) -> 75.414969 | L8: =IF(G8=0,"",MIN(Huawei!$F$3:$F$17)) -> 3690 | M8: =IF(G8=0,"",QUARTILE(Huawei!$F$3:$F$17,1)) -> 4035 | N8: =IF(G8=0,"",QUARTILE(Huawei!$F$3:$F$17,3)) -> 17400 | O8: =IF(G8=0,"",MAX(Huawei!$F$3:$F$17)) -> 23900 | P8: =COUNT(Huawei!$G$3:$G$17) -> 9 | Q8: =IF(P8=0,"",AVERAGE(Huawei!$G$3:$G$17)) -> 4.9666667 | R8: =IF(P8=0,"",MEDIAN(Huawei!$G$3:$G$17)) -> 5 | S8: =IF(P8<2,"",STDEV(Huawei!$G$3:$G$17)) -> 0.05 | T8: =IF(OR(P8<2,Q8=0),"",S8/Q8*100) -> 1.0067114 | U8: =IF(P8=0,"",MIN(Huawei!$G$3:$G$17)) -> 4.9 | V8: =IF(P8=0,"",QUARTILE(Huawei!$G$3:$G$17,1)) -> 4.9 | W8: =IF(P8=0,"",QUARTILE(Huawei!$G$3:$G$17,3)) -> 5 | X8: =IF(P8=0,"",MAX(Huawei!$G$3:$G$17)) -> 5
B9: Model | C9: Premium Standard (Gen 1) | D9: Apple | E9: Apple Watch Series 9 | G9: =COUNT(Apple_S9!$F$3:$F$3) -> 1 | H9: =IF(G9=0,"",AVERAGE(Apple_S9!$F$3:$F$3)) -> 20900 | I9: =IF(G9=0,"",MEDIAN(Apple_S9!$F$3:$F$3)) -> 20900 | J9: =IF(G9<2,"",STDEV(Apple_S9!$F$3:$F$3)) | K9: =IF(OR(G9<2,H9=0),"",J9/H9*100) | L9: =IF(G9=0,"",MIN(Apple_S9!$F$3:$F$3)) -> 20900 | M9: =IF(G9=0,"",QUARTILE(Apple_S9!$F$3:$F$3,1)) -> 20900 | N9: =IF(G9=0,"",QUARTILE(Apple_S9!$F$3:$F$3,3)) -> 20900 | O9: =IF(G9=0,"",MAX(Apple_S9!$F$3:$F$3)) -> 20900 | P9: =COUNT(Apple_S9!$G$3:$G$3) -> 1 | Q9: =IF(P9=0,"",AVERAGE(Apple_S9!$G$3:$G$3)) -> 5 | R9: =IF(P9=0,"",MEDIAN(Apple_S9!$G$3:$G$3)) -> 5 | S9: =IF(P9<2,"",STDEV(Apple_S9!$G$3:$G$3)) | T9: =IF(OR(P9<2,Q9=0),"",S9/Q9*100) | U9: =IF(P9=0,"",MIN(Apple_S9!$G$3:$G$3)) -> 5 | V9: =IF(P9=0,"",QUARTILE(Apple_S9!$G$3:$G$3,1)) -> 5 | W9: =IF(P9=0,"",QUARTILE(Apple_S9!$G$3:$G$3,3)) -> 5 | X9: =IF(P9=0,"",MAX(Apple_S9!$G$3:$G$3)) -> 5
B10: Model | C10: Premium Standard (Gen 1) | D10: Samsung | E10: Galaxy Watch7 | G10: =COUNT(Galaxy_Watch7!$F$3:$F$28) -> 26 | H10: =IF(G10=0,"",AVERAGE(Galaxy_Watch7!$F$3:$F$28)) -> 5944.4146 | I10: =IF(G10=0,"",MEDIAN(Galaxy_Watch7!$F$3:$F$28)) -> 6444.5 | J10: =IF(G10<2,"",STDEV(Galaxy_Watch7!$F$3:$F$28)) -> 5116.309 | K10: =IF(OR(G10<2,H10=0),"",J10/H10*100) -> 86.069182 | L10: =IF(G10=0,"",MIN(Galaxy_Watch7!$F$3:$F$28)) -> 429 | M10: =IF(G10=0,"",QUARTILE(Galaxy_Watch7!$F$3:$F$28,1)) -> 1045.77 | N10: =IF(G10=0,"",QUARTILE(Galaxy_Watch7!$F$3:$F$28,3)) -> 9259.5 | O10: =IF(G10=0,"",MAX(Galaxy_Watch7!$F$3:$F$28)) -> 20995 | P10: =COUNT(Galaxy_Watch7!$G$3:$G$28) -> 16 | Q10: =IF(P10=0,"",AVERAGE(Galaxy_Watch7!$G$3:$G$28)) -> 4.8625 | R10: =IF(P10=0,"",MEDIAN(Galaxy_Watch7!$G$3:$G$28)) -> 5 | S10: =IF(P10<2,"",STDEV(Galaxy_Watch7!$G$3:$G$28)) -> 0.27537853 | T10: =IF(OR(P10<2,Q10=0),"",S10/Q10*100) -> 5.6633116 | U10: =IF(P10=0,"",MIN(Galaxy_Watch7!$G$3:$G$28)) -> 4 | V10: =IF(P10=0,"",QUARTILE(Galaxy_Watch7!$G$3:$G$28,1)) -> 4.9 | W10: =IF(P10=0,"",QUARTILE(Galaxy_Watch7!$G$3:$G$28,3)) -> 5 | X10: =IF(P10=0,"",MAX(Galaxy_Watch7!$G$3:$G$28)) -> 5
B11: Model | C11: Premium Standard (Gen 1) | D11: Huawei | E11: Huawei Watch GT 4 | G11: =COUNT(Huawei_GT4!$F$3:$F$8) -> 6 | H11: =IF(G11=0,"",AVERAGE(Huawei_GT4!$F$3:$F$8)) -> 5358.3333 | I11: =IF(G11=0,"",MEDIAN(Huawei_GT4!$F$3:$F$8)) -> 3990 | J11: =IF(G11<2,"",STDEV(Huawei_GT4!$F$3:$F$8)) -> 2496.2405 | K11: =IF(OR(G11<2,H11=0),"",J11/H11*100) -> 46.586137 | L11: =IF(G11=0,"",MIN(Huawei_GT4!$F$3:$F$8)) -> 3690 | M11: =IF(G11=0,"",QUARTILE(Huawei_GT4!$F$3:$F$8,1)) -> 3990 | N11: =IF(G11=0,"",QUARTILE(Huawei_GT4!$F$3:$F$8,3)) -> 5872.5 | O11: =IF(G11=0,"",MAX(Huawei_GT4!$F$3:$F$8)) -> 9990 | P11: =COUNT(Huawei_GT4!$G$3:$G$8) -> 3 | Q11: =IF(P11=0,"",AVERAGE(Huawei_GT4!$G$3:$G$8)) -> 4.9666667 | R11: =IF(P11=0,"",MEDIAN(Huawei_GT4!$G$3:$G$8)) -> 5 | S11: =IF(P11<2,"",STDEV(Huawei_GT4!$G$3:$G$8)) -> 0.057735027 | T11: =IF(OR(P11<2,Q11=0),"",S11/Q11*100) -> 1.1624502 | U11: =IF(P11=0,"",MIN(Huawei_GT4!$G$3:$G$8)) -> 4.9 | V11: =IF(P11=0,"",QUARTILE(Huawei_GT4!$G$3:$G$8,1)) -> 4.95 | W11: =IF(P11=0,"",QUARTILE(Huawei_GT4!$G$3:$G$8,3)) -> 5 | X11: =IF(P11=0,"",MAX(Huawei_GT4!$G$3:$G$8)) -> 5
B12: Model | C12: Premium Standard (Gen 2) | D12: Apple | E12: Apple Watch Series 10 | G12: =COUNT(Apple_S10!$F$3:$F$5) -> 3 | H12: =IF(G12=0,"",AVERAGE(Apple_S10!$F$3:$F$5)) -> 20410 | I12: =IF(G12=0,"",MEDIAN(Apple_S10!$F$3:$F$5)) -> 18130 | J12: =IF(G12<2,"",STDEV(Apple_S10!$F$3:$F$5)) -> 5985.0898 | K12: =IF(OR(G12<2,H12=0),"",J12/H12*100) -> 29.324301 | L12: =IF(G12=0,"",MIN(Apple_S10!$F$3:$F$5)) -> 15900 | M12: =IF(G12=0,"",QUARTILE(Apple_S10!$F$3:$F$5,1)) -> 17015 | N12: =IF(G12=0,"",QUARTILE(Apple_S10!$F$3:$F$5,3)) -> 22665 | O12: =IF(G12=0,"",MAX(Apple_S10!$F$3:$F$5)) -> 27200 | P12: =COUNT(Apple_S10!$G$3:$G$5) -> 3 | Q12: =IF(P12=0,"",AVERAGE(Apple_S10!$G$3:$G$5)) -> 4.9333333 | R12: =IF(P12=0,"",MEDIAN(Apple_S10!$G$3:$G$5)) -> 5 | S12: =IF(P12<2,"",STDEV(Apple_S10!$G$3:$G$5)) -> 0.11547005 | T12: =IF(OR(P12<2,Q12=0),"",S12/Q12*100) -> 2.3406092 | U12: =IF(P12=0,"",MIN(Apple_S10!$G$3:$G$5)) -> 4.8 | V12: =IF(P12=0,"",QUARTILE(Apple_S10!$G$3:$G$5,1)) -> 4.9 | W12: =IF(P12=0,"",QUARTILE(Apple_S10!$G$3:$G$5,3)) -> 5 | X12: =IF(P12=0,"",MAX(Apple_S10!$G$3:$G$5)) -> 5
B13: Model | C13: Premium Standard (Gen 2) | D13: Samsung | E13: Galaxy Watch8 | G13: =COUNT(Galaxy_Watch8!$F$3:$F$40) -> 38 | H13: =IF(G13=0,"",AVERAGE(Galaxy_Watch8!$F$3:$F$40)) -> 10304.918 | I13: =IF(G13=0,"",MEDIAN(Galaxy_Watch8!$F$3:$F$40)) -> 10295 | J13: =IF(G13<2,"",STDEV(Galaxy_Watch8!$F$3:$F$40)) -> 3333.1396 | K13: =IF(OR(G13<2,H13=0),"",J13/H13*100) -> 32.345136 | L13: =IF(G13=0,"",MIN(Galaxy_Watch8!$F$3:$F$40)) -> 5120 | M13: =IF(G13=0,"",QUARTILE(Galaxy_Watch8!$F$3:$F$40,1)) -> 7790 | N13: =IF(G13=0,"",QUARTILE(Galaxy_Watch8!$F$3:$F$40,3)) -> 12588 | O13: =IF(G13=0,"",MAX(Galaxy_Watch8!$F$3:$F$40)) -> 16703 | P13: =COUNT(Galaxy_Watch8!$G$3:$G$40) -> 24 | Q13: =IF(P13=0,"",AVERAGE(Galaxy_Watch8!$G$3:$G$40)) -> 4.8125 | R13: =IF(P13=0,"",MEDIAN(Galaxy_Watch8!$G$3:$G$40)) -> 5 | S13: =IF(P13<2,"",STDEV(Galaxy_Watch8!$G$3:$G$40)) -> 0.81470854 | T13: =IF(OR(P13<2,Q13=0),"",S13/Q13*100) -> 16.929009 | U13: =IF(P13=0,"",MIN(Galaxy_Watch8!$G$3:$G$40)) -> 1 | V13: =IF(P13=0,"",QUARTILE(Galaxy_Watch8!$G$3:$G$40,1)) -> 5 | W13: =IF(P13=0,"",QUARTILE(Galaxy_Watch8!$G$3:$G$40,3)) -> 5 | X13: =IF(P13=0,"",MAX(Galaxy_Watch8!$G$3:$G$40)) -> 5
B14: Model | C14: Premium Standard (Gen 2) | D14: Huawei | E14: Huawei Watch GT 5 | G14: =COUNT(Huawei_GT5!$F$3:$F$7) -> 5 | H14: =IF(G14=0,"",AVERAGE(Huawei_GT5!$F$3:$F$7)) -> 8006.14 | I14: =IF(G14=0,"",MEDIAN(Huawei_GT5!$F$3:$F$7)) -> 4990 | J14: =IF(G14<2,"",STDEV(Huawei_GT5!$F$3:$F$7)) -> 7263.6954 | K14: =IF(OR(G14<2,H14=0),"",J14/H14*100) -> 90.72656 | L14: =IF(G14=0,"",MIN(Huawei_GT5!$F$3:$F$7)) -> 4080 | M14: =IF(G14=0,"",QUARTILE(Huawei_GT5!$F$3:$F$7,1)) -> 4990 | N14: =IF(G14=0,"",QUARTILE(Huawei_GT5!$F$3:$F$7,3)) -> 4990 | O14: =IF(G14=0,"",MAX(Huawei_GT5!$F$3:$F$7)) -> 20980.7 | P14: =COUNT(Huawei_GT5!$G$3:$G$7) -> 4 | Q14: =IF(P14=0,"",AVERAGE(Huawei_GT5!$G$3:$G$7)) -> 4.975 | R14: =IF(P14=0,"",MEDIAN(Huawei_GT5!$G$3:$G$7)) -> 5 | S14: =IF(P14<2,"",STDEV(Huawei_GT5!$G$3:$G$7)) -> 0.05 | T14: =IF(OR(P14<2,Q14=0),"",S14/Q14*100) -> 1.0050251 | U14: =IF(P14=0,"",MIN(Huawei_GT5!$G$3:$G$7)) -> 4.9 | V14: =IF(P14=0,"",QUARTILE(Huawei_GT5!$G$3:$G$7,1)) -> 4.975 | W14: =IF(P14=0,"",QUARTILE(Huawei_GT5!$G$3:$G$7,3)) -> 5 | X14: =IF(P14=0,"",MAX(Huawei_GT5!$G$3:$G$7)) -> 5
B15: Model | C15: Premium Sport | D15: Apple | E15: Apple Watch Ultra 2 | G15: =0 -> 0 | P15: =0 -> 0
B16: Model | C16: Premium Sport | D16: Samsung | E16: Galaxy Watch Ultra | G16: =COUNT(Galaxy_Ultra!$F$3:$F$34) -> 32 | H16: =IF(G16=0,"",AVERAGE(Galaxy_Ultra!$F$3:$F$34)) -> 19000.125 | I16: =IF(G16=0,"",MEDIAN(Galaxy_Ultra!$F$3:$F$34)) -> 17685 | J16: =IF(G16<2,"",STDEV(Galaxy_Ultra!$F$3:$F$34)) -> 6781.5315 | K16: =IF(OR(G16<2,H16=0),"",J16/H16*100) -> 35.692036 | L16: =IF(G16=0,"",MIN(Galaxy_Ultra!$F$3:$F$34)) -> 6500 | M16: =IF(G16=0,"",QUARTILE(Galaxy_Ultra!$F$3:$F$34,1)) -> 14212.5 | N16: =IF(G16=0,"",QUARTILE(Galaxy_Ultra!$F$3:$F$34,3)) -> 23360 | O16: =IF(G16=0,"",MAX(Galaxy_Ultra!$F$3:$F$34)) -> 34055 | P16: =COUNT(Galaxy_Ultra!$G$3:$G$34) -> 20 | Q16: =IF(P16=0,"",AVERAGE(Galaxy_Ultra!$G$3:$G$34)) -> 4.805 | R16: =IF(P16=0,"",MEDIAN(Galaxy_Ultra!$G$3:$G$34)) -> 5 | S16: =IF(P16<2,"",STDEV(Galaxy_Ultra!$G$3:$G$34)) -> 0.48392583 | T16: =IF(OR(P16<2,Q16=0),"",S16/Q16*100) -> 10.071297 | U16: =IF(P16=0,"",MIN(Galaxy_Ultra!$G$3:$G$34)) -> 3 | V16: =IF(P16=0,"",QUARTILE(Galaxy_Ultra!$G$3:$G$34,1)) -> 4.9 | W16: =IF(P16=0,"",QUARTILE(Galaxy_Ultra!$G$3:$G$34,3)) -> 5 | X16: =IF(P16=0,"",MAX(Galaxy_Ultra!$G$3:$G$34)) -> 5
B17: Model | C17: Premium Sport | D17: Huawei | E17: Huawei Watch Ultimate | G17: =COUNT(Huawei_Ultimate!$F$3:$F$6) -> 4 | H17: =IF(G17=0,"",AVERAGE(Huawei_Ultimate!$F$3:$F$6)) -> 19650 | I17: =IF(G17=0,"",MEDIAN(Huawei_Ultimate!$F$3:$F$6)) -> 19900 | J17: =IF(G17<2,"",STDEV(Huawei_Ultimate!$F$3:$F$6)) -> 3685.5574 | K17: =IF(OR(G17<2,H17=0),"",J17/H17*100) -> 18.756017 | L17: =IF(G17=0,"",MIN(Huawei_Ultimate!$F$3:$F$6)) -> 14900 | M17: =IF(G17=0,"",QUARTILE(Huawei_Ultimate!$F$3:$F$6,1)) -> 18650 | N17: =IF(G17=0,"",QUARTILE(Huawei_Ultimate!$F$3:$F$6,3)) -> 20900 | O17: =IF(G17=0,"",MAX(Huawei_Ultimate!$F$3:$F$6)) -> 23900 | P17: =COUNT(Huawei_Ultimate!$G$3:$G$6) -> 2 | Q17: =IF(P17=0,"",AVERAGE(Huawei_Ultimate!$G$3:$G$6)) -> 4.95 | R17: =IF(P17=0,"",MEDIAN(Huawei_Ultimate!$G$3:$G$6)) -> 4.95 | S17: =IF(P17<2,"",STDEV(Huawei_Ultimate!$G$3:$G$6)) -> 0.070710678 | T17: =IF(OR(P17<2,Q17=0),"",S17/Q17*100) -> 1.4284985 | U17: =IF(P17=0,"",MIN(Huawei_Ultimate!$G$3:$G$6)) -> 4.9 | V17: =IF(P17=0,"",QUARTILE(Huawei_Ultimate!$G$3:$G$6,1)) -> 4.925 | W17: =IF(P17=0,"",QUARTILE(Huawei_Ultimate!$G$3:$G$6,3)) -> 4.975 | X17: =IF(P17=0,"",MAX(Huawei_Ultimate!$G$3:$G$6)) -> 5
B18: Model × Platform | C18: Premium Standard (Gen 1) | D18: Apple | E18: Apple Watch Series 9 | F18: Lazada | G18: =COUNT(Apple_S9!$F$3:$F$3) -> 1 | H18: =IF(G18=0,"",AVERAGE(Apple_S9!$F$3:$F$3)) -> 20900 | I18: =IF(G18=0,"",MEDIAN(Apple_S9!$F$3:$F$3)) -> 20900 | J18: =IF(G18<2,"",STDEV(Apple_S9!$F$3:$F$3)) | K18: =IF(OR(G18<2,H18=0),"",J18/H18*100) | L18: =IF(G18=0,"",MIN(Apple_S9!$F$3:$F$3)) -> 20900 | M18: =IF(G18=0,"",QUARTILE(Apple_S9!$F$3:$F$3,1)) -> 20900 | N18: =IF(G18=0,"",QUARTILE(Apple_S9!$F$3:$F$3,3)) -> 20900 | O18: =IF(G18=0,"",MAX(Apple_S9!$F$3:$F$3)) -> 20900 | P18: =COUNT(Apple_S9!$G$3:$G$3) -> 1 | Q18: =IF(P18=0,"",AVERAGE(Apple_S9!$G$3:$G$3)) -> 5 | R18: =IF(P18=0,"",MEDIAN(Apple_S9!$G$3:$G$3)) -> 5 | S18: =IF(P18<2,"",STDEV(Apple_S9!$G$3:$G$3)) | T18: =IF(OR(P18<2,Q18=0),"",S18/Q18*100) | U18: =IF(P18=0,"",MIN(Apple_S9!$G$3:$G$3)) -> 5 | V18: =IF(P18=0,"",QUARTILE(Apple_S9!$G$3:$G$3,1)) -> 5 | W18: =IF(P18=0,"",QUARTILE(Apple_S9!$G$3:$G$3,3)) -> 5 | X18: =IF(P18=0,"",MAX(Apple_S9!$G$3:$G$3)) -> 5
B19: Model × Platform | C19: Premium Standard (Gen 1) | D19: Apple | E19: Apple Watch Series 9 | F19: Shopee | G19: =0 -> 0 | P19: =0 -> 0
B20: Model × Platform | C20: Premium Standard (Gen 1) | D20: Samsung | E20: Galaxy Watch7 | F20: Lazada | G20: =COUNT(Galaxy_Watch7!$F$3:$F$15) -> 13 | H20: =IF(G20=0,"",AVERAGE(Galaxy_Watch7!$F$3:$F$15)) -> 4281.5985 | I20: =IF(G20=0,"",MEDIAN(Galaxy_Watch7!$F$3:$F$15)) -> 3500 | J20: =IF(G20<2,"",STDEV(Galaxy_Watch7!$F$3:$F$15)) -> 3829.861 | K20: =IF(OR(G20<2,H20=0),"",J20/H20*100) -> 89.449326 | L20: =IF(G20=0,"",MIN(Galaxy_Watch7!$F$3:$F$15)) -> 566.35 | M20: =IF(G20=0,"",QUARTILE(Galaxy_Watch7!$F$3:$F$15,1)) -> 1045.21 | N20: =IF(G20=0,"",QUARTILE(Galaxy_Watch7!$F$3:$F$15,3)) -> 6999 | O20: =IF(G20=0,"",MAX(Galaxy_Watch7!$F$3:$F$15)) -> 10900 | P20: =COUNT(Galaxy_Watch7!$G$3:$G$15) -> 4 | Q20: =IF(P20=0,"",AVERAGE(Galaxy_Watch7!$G$3:$G$15)) -> 5 | R20: =IF(P20=0,"",MEDIAN(Galaxy_Watch7!$G$3:$G$15)) -> 5 | S20: =IF(P20<2,"",STDEV(Galaxy_Watch7!$G$3:$G$15)) -> 0 | T20: =IF(OR(P20<2,Q20=0),"",S20/Q20*100) -> 0 | U20: =IF(P20=0,"",MIN(Galaxy_Watch7!$G$3:$G$15)) -> 5 | V20: =IF(P20=0,"",QUARTILE(Galaxy_Watch7!$G$3:$G$15,1)) -> 5 | W20: =IF(P20=0,"",QUARTILE(Galaxy_Watch7!$G$3:$G$15,3)) -> 5 | X20: =IF(P20=0,"",MAX(Galaxy_Watch7!$G$3:$G$15)) -> 5
B21: Model × Platform | C21: Premium Standard (Gen 1) | D21: Samsung | E21: Galaxy Watch7 | F21: Shopee | G21: =COUNT(Galaxy_Watch7!$F$16:$F$28) -> 13 | H21: =IF(G21=0,"",AVERAGE(Galaxy_Watch7!$F$16:$F$28)) -> 7607.2308 | I21: =IF(G21=0,"",MEDIAN(Galaxy_Watch7!$F$16:$F$28)) -> 7990 | J21: =IF(G21<2,"",STDEV(Galaxy_Watch7!$F$16:$F$28)) -> 5820.3131 | K21: =IF(OR(G21<2,H21=0),"",J21/H21*100) -> 76.510274 | L21: =IF(G21=0,"",MIN(Galaxy_Watch7!$F$16:$F$28)) -> 429 | M21: =IF(G21=0,"",QUARTILE(Galaxy_Watch7!$F$16:$F$28,1)) -> 1624 | N21: =IF(G21=0,"",QUARTILE(Galaxy_Watch7!$F$16:$F$28,3)) -> 10659 | O21: =IF(G21=0,"",MAX(Galaxy_Watch7!$F$16:$F$28)) -> 20995 | P21: =COUNT(Galaxy_Watch7!$G$16:$G$28) -> 12 | Q21: =IF(P21=0,"",AVERAGE(Galaxy_Watch7!$G$16:$G$28)) -> 4.8166667 | R21: =IF(P21=0,"",MEDIAN(Galaxy_Watch7!$G$16:$G$28)) -> 4.9 | S21: =IF(P21<2,"",STDEV(Galaxy_Watch7!$G$16:$G$28)) -> 0.30698929 | T21: =IF(OR(P21<2,Q21=0),"",S21/Q21*100) -> 6.3734801 | U21: =IF(P21=0,"",MIN(Galaxy_Watch7!$G$16:$G$28)) -> 4 | V21: =IF(P21=0,"",QUARTILE(Galaxy_Watch7!$G$16:$G$28,1)) -> 4.875 | W21: =IF(P21=0,"",QUARTILE(Galaxy_Watch7!$G$16:$G$28,3)) -> 5 | X21: =IF(P21=0,"",MAX(Galaxy_Watch7!$G$16:$G$28)) -> 5
B22: Model × Platform | C22: Premium Standard (Gen 1) | D22: Huawei | E22: Huawei Watch GT 4 | F22: Lazada | G22: =COUNT(Huawei_GT4!$F$3:$F$6) -> 4 | H22: =IF(G22=0,"",AVERAGE(Huawei_GT4!$F$3:$F$6)) -> 5490 | I22: =IF(G22=0,"",MEDIAN(Huawei_GT4!$F$3:$F$6)) -> 3990 | J22: =IF(G22<2,"",STDEV(Huawei_GT4!$F$3:$F$6)) -> 3000 | K22: =IF(OR(G22<2,H22=0),"",J22/H22*100) -> 54.644809 | L22: =IF(G22=0,"",MIN(Huawei_GT4!$F$3:$F$6)) -> 3990 | M22: =IF(G22=0,"",QUARTILE(Huawei_GT4!$F$3:$F$6,1)) -> 3990 | N22: =IF(G22=0,"",QUARTILE(Huawei_GT4!$F$3:$F$6,3)) -> 5490 | O22: =IF(G22=0,"",MAX(Huawei_GT4!$F$3:$F$6)) -> 9990 | P22: =COUNT(Huawei_GT4!$G$3:$G$6) -> 1 | Q22: =IF(P22=0,"",AVERAGE(Huawei_GT4!$G$3:$G$6)) -> 5 | R22: =IF(P22=0,"",MEDIAN(Huawei_GT4!$G$3:$G$6)) -> 5 | S22: =IF(P22<2,"",STDEV(Huawei_GT4!$G$3:$G$6)) | T22: =IF(OR(P22<2,Q22=0),"",S22/Q22*100) | U22: =IF(P22=0,"",MIN(Huawei_GT4!$G$3:$G$6)) -> 5 | V22: =IF(P22=0,"",QUARTILE(Huawei_GT4!$G$3:$G$6,1)) -> 5 | W22: =IF(P22=0,"",QUARTILE(Huawei_GT4!$G$3:$G$6,3)) -> 5 | X22: =IF(P22=0,"",MAX(Huawei_GT4!$G$3:$G$6)) -> 5
B23: Model × Platform | C23: Premium Standard (Gen 1) | D23: Huawei | E23: Huawei Watch GT 4 | F23: Shopee | G23: =COUNT(Huawei_GT4!$F$7:$F$8) -> 2 | H23: =IF(G23=0,"",AVERAGE(Huawei_GT4!$F$7:$F$8)) -> 5095 | I23: =IF(G23=0,"",MEDIAN(Huawei_GT4!$F$7:$F$8)) -> 5095 | J23: =IF(G23<2,"",STDEV(Huawei_GT4!$F$7:$F$8)) -> 1986.9701 | K23: =IF(OR(G23<2,H23=0),"",J23/H23*100) -> 38.998431 | L23: =IF(G23=0,"",MIN(Huawei_GT4!$F$7:$F$8)) -> 3690 | M23: =IF(G23=0,"",QUARTILE(Huawei_GT4!$F$7:$F$8,1)) -> 4392.5 | N23: =IF(G23=0,"",QUARTILE(Huawei_GT4!$F$7:$F$8,3)) -> 5797.5 | O23: =IF(G23=0,"",MAX(Huawei_GT4!$F$7:$F$8)) -> 6500 | P23: =COUNT(Huawei_GT4!$G$7:$G$8) -> 2 | Q23: =IF(P23=0,"",AVERAGE(Huawei_GT4!$G$7:$G$8)) -> 4.95 | R23: =IF(P23=0,"",MEDIAN(Huawei_GT4!$G$7:$G$8)) -> 4.95 | S23: =IF(P23<2,"",STDEV(Huawei_GT4!$G$7:$G$8)) -> 0.070710678 | T23: =IF(OR(P23<2,Q23=0),"",S23/Q23*100) -> 1.4284985 | U23: =IF(P23=0,"",MIN(Huawei_GT4!$G$7:$G$8)) -> 4.9 | V23: =IF(P23=0,"",QUARTILE(Huawei_GT4!$G$7:$G$8,1)) -> 4.925 | W23: =IF(P23=0,"",QUARTILE(Huawei_GT4!$G$7:$G$8,3)) -> 4.975 | X23: =IF(P23=0,"",MAX(Huawei_GT4!$G$7:$G$8)) -> 5
B24: Model × Platform | C24: Premium Standard (Gen 2) | D24: Apple | E24: Apple Watch Series 10 | F24: Lazada | G24: =COUNT(Apple_S10!$F$3:$F$3) -> 1 | H24: =IF(G24=0,"",AVERAGE(Apple_S10!$F$3:$F$3)) -> 15900 | I24: =IF(G24=0,"",MEDIAN(Apple_S10!$F$3:$F$3)) -> 15900 | J24: =IF(G24<2,"",STDEV(Apple_S10!$F$3:$F$3)) | K24: =IF(OR(G24<2,H24=0),"",J24/H24*100) | L24: =IF(G24=0,"",MIN(Apple_S10!$F$3:$F$3)) -> 15900 | M24: =IF(G24=0,"",QUARTILE(Apple_S10!$F$3:$F$3,1)) -> 15900 | N24: =IF(G24=0,"",QUARTILE(Apple_S10!$F$3:$F$3,3)) -> 15900 | O24: =IF(G24=0,"",MAX(Apple_S10!$F$3:$F$3)) -> 15900 | P24: =COUNT(Apple_S10!$G$3:$G$3) -> 1 | Q24: =IF(P24=0,"",AVERAGE(Apple_S10!$G$3:$G$3)) -> 5 | R24: =IF(P24=0,"",MEDIAN(Apple_S10!$G$3:$G$3)) -> 5 | S24: =IF(P24<2,"",STDEV(Apple_S10!$G$3:$G$3)) | T24: =IF(OR(P24<2,Q24=0),"",S24/Q24*100) | U24: =IF(P24=0,"",MIN(Apple_S10!$G$3:$G$3)) -> 5 | V24: =IF(P24=0,"",QUARTILE(Apple_S10!$G$3:$G$3,1)) -> 5 | W24: =IF(P24=0,"",QUARTILE(Apple_S10!$G$3:$G$3,3)) -> 5 | X24: =IF(P24=0,"",MAX(Apple_S10!$G$3:$G$3)) -> 5
B25: Model × Platform | C25: Premium Standard (Gen 2) | D25: Apple | E25: Apple Watch Series 10 | F25: Shopee | G25: =COUNT(Apple_S10!$F$4:$F$5) -> 2 | H25: =IF(G25=0,"",AVERAGE(Apple_S10!$F$4:$F$5)) -> 22665 | I25: =IF(G25=0,"",MEDIAN(Apple_S10!$F$4:$F$5)) -> 22665 | J25: =IF(G25<2,"",STDEV(Apple_S10!$F$4:$F$5)) -> 6413.4585 | K25: =IF(OR(G25<2,H25=0),"",J25/H25*100) -> 28.296751 | L25: =IF(G25=0,"",MIN(Apple_S10!$F$4:$F$5)) -> 18130 | M25: =IF(G25=0,"",QUARTILE(Apple_S10!$F$4:$F$5,1)) -> 20397.5 | N25: =IF(G25=0,"",QUARTILE(Apple_S10!$F$4:$F$5,3)) -> 24932.5 | O25: =IF(G25=0,"",MAX(Apple_S10!$F$4:$F$5)) -> 27200 | P25: =COUNT(Apple_S10!$G$4:$G$5) -> 2 | Q25: =IF(P25=0,"",AVERAGE(Apple_S10!$G$4:$G$5)) -> 4.9 | R25: =IF(P25=0,"",MEDIAN(Apple_S10!$G$4:$G$5)) -> 4.9 | S25: =IF(P25<2,"",STDEV(Apple_S10!$G$4:$G$5)) -> 0.14142136 | T25: =IF(OR(P25<2,Q25=0),"",S25/Q25*100) -> 2.8861501 | U25: =IF(P25=0,"",MIN(Apple_S10!$G$4:$G$5)) -> 4.8 | V25: =IF(P25=0,"",QUARTILE(Apple_S10!$G$4:$G$5,1)) -> 4.85 | W25: =IF(P25=0,"",QUARTILE(Apple_S10!$G$4:$G$5,3)) -> 4.95 | X25: =IF(P25=0,"",MAX(Apple_S10!$G$4:$G$5)) -> 5
B26: Model × Platform | C26: Premium Standard (Gen 2) | D26: Samsung | E26: Galaxy Watch8 | F26: Lazada | G26: =COUNT(Galaxy_Watch8!$F$3:$F$25) -> 23 | H26: =IF(G26=0,"",AVERAGE(Galaxy_Watch8!$F$3:$F$25)) -> 9707.1248 | I26: =IF(G26=0,"",MEDIAN(Galaxy_Watch8!$F$3:$F$25)) -> 10000 | J26: =IF(G26<2,"",STDEV(Galaxy_Watch8!$F$3:$F$25)) -> 3271.3554 | K26: =IF(OR(G26<2,H26=0),"",J26/H26*100) -> 33.70056 | L26: =IF(G26=0,"",MIN(Galaxy_Watch8!$F$3:$F$25)) -> 5120 | M26: =IF(G26=0,"",QUARTILE(Galaxy_Watch8!$F$3:$F$25,1)) -> 6633.435 | N26: =IF(G26=0,"",QUARTILE(Galaxy_Watch8!$F$3:$F$25,3)) -> 12307 | O26: =IF(G26=0,"",MAX(Galaxy_Watch8!$F$3:$F$25)) -> 15619 | P26: =COUNT(Galaxy_Watch8!$G$3:$G$25) -> 10 | Q26: =IF(P26=0,"",AVERAGE(Galaxy_Watch8!$G$3:$G$25)) -> 4.57 | R26: =IF(P26=0,"",MEDIAN(Galaxy_Watch8!$G$3:$G$25)) -> 5 | S26: =IF(P26<2,"",STDEV(Galaxy_Watch8!$G$3:$G$25)) -> 1.2579083 | T26: =IF(OR(P26<2,Q26=0),"",S26/Q26*100) -> 27.525346 | U26: =IF(P26=0,"",MIN(Galaxy_Watch8!$G$3:$G$25)) -> 1 | V26: =IF(P26=0,"",QUARTILE(Galaxy_Watch8!$G$3:$G$25,1)) -> 5 | W26: =IF(P26=0,"",QUARTILE(Galaxy_Watch8!$G$3:$G$25,3)) -> 5 | X26: =IF(P26=0,"",MAX(Galaxy_Watch8!$G$3:$G$25)) -> 5
B27: Model × Platform | C27: Premium Standard (Gen 2) | D27: Samsung | E27: Galaxy Watch8 | F27: Shopee | G27: =COUNT(Galaxy_Watch8!$F$26:$F$40) -> 15 | H27: =IF(G27=0,"",AVERAGE(Galaxy_Watch8!$F$26:$F$40)) -> 11221.533 | I27: =IF(G27=0,"",MEDIAN(Galaxy_Watch8!$F$26:$F$40)) -> 10590 | J27: =IF(G27<2,"",STDEV(Galaxy_Watch8!$F$26:$F$40)) -> 3325.2553 | K27: =IF(OR(G27<2,H27=0),"",J27/H27*100) -> 29.632807 | L27: =IF(G27=0,"",MIN(Galaxy_Watch8!$F$26:$F$40)) -> 6980 | M27: =IF(G27=0,"",QUARTILE(Galaxy_Watch8!$F$26:$F$40,1)) -> 8590 | N27: =IF(G27=0,"",QUARTILE(Galaxy_Watch8!$F$26:$F$40,3)) -> 14039 | O27: =IF(G27=0,"",MAX(Galaxy_Watch8!$F$26:$F$40)) -> 16703 | P27: =COUNT(Galaxy_Watch8!$G$26:$G$40) -> 14 | Q27: =IF(P27=0,"",AVERAGE(Galaxy_Watch8!$G$26:$G$40)) -> 4.9857143 | R27: =IF(P27=0,"",MEDIAN(Galaxy_Watch8!$G$26:$G$40)) -> 5 | S27: =IF(P27<2,"",STDEV(Galaxy_Watch8!$G$26:$G$40)) -> 0.036313652 | T27: =IF(OR(P27<2,Q27=0),"",S27/Q27*100) -> 0.72835405 | U27: =IF(P27=0,"",MIN(Galaxy_Watch8!$G$26:$G$40)) -> 4.9 | V27: =IF(P27=0,"",QUARTILE(Galaxy_Watch8!$G$26:$G$40,1)) -> 5 | W27: =IF(P27=0,"",QUARTILE(Galaxy_Watch8!$G$26:$G$40,3)) -> 5 | X27: =IF(P27=0,"",MAX(Galaxy_Watch8!$G$26:$G$40)) -> 5
B28: Model × Platform | C28: Premium Standard (Gen 2) | D28: Huawei | E28: Huawei Watch GT 5 | F28: Lazada | G28: =COUNT(Huawei_GT5!$F$3:$F$4) -> 2 | H28: =IF(G28=0,"",AVERAGE(Huawei_GT5!$F$3:$F$4)) -> 12985.35 | I28: =IF(G28=0,"",MEDIAN(Huawei_GT5!$F$3:$F$4)) -> 12985.35 | J28: =IF(G28<2,"",STDEV(Huawei_GT5!$F$3:$F$4)) -> 11307.132 | K28: =IF(OR(G28<2,H28=0),"",J28/H28*100) -> 87.07607 | L28: =IF(G28=0,"",MIN(Huawei_GT5!$F$3:$F$4)) -> 4990 | M28: =IF(G28=0,"",QUARTILE(Huawei_GT5!$F$3:$F$4,1)) -> 8987.675 | N28: =IF(G28=0,"",QUARTILE(Huawei_GT5!$F$3:$F$4,3)) -> 16983.025 | O28: =IF(G28=0,"",MAX(Huawei_GT5!$F$3:$F$4)) -> 20980.7 | P28: =COUNT(Huawei_GT5!$G$3:$G$4) -> 1 | Q28: =IF(P28=0,"",AVERAGE(Huawei_GT5!$G$3:$G$4)) -> 5 | R28: =IF(P28=0,"",MEDIAN(Huawei_GT5!$G$3:$G$4)) -> 5 | S28: =IF(P28<2,"",STDEV(Huawei_GT5!$G$3:$G$4)) | T28: =IF(OR(P28<2,Q28=0),"",S28/Q28*100) | U28: =IF(P28=0,"",MIN(Huawei_GT5!$G$3:$G$4)) -> 5 | V28: =IF(P28=0,"",QUARTILE(Huawei_GT5!$G$3:$G$4,1)) -> 5 | W28: =IF(P28=0,"",QUARTILE(Huawei_GT5!$G$3:$G$4,3)) -> 5 | X28: =IF(P28=0,"",MAX(Huawei_GT5!$G$3:$G$4)) -> 5
B29: Model × Platform | C29: Premium Standard (Gen 2) | D29: Huawei | E29: Huawei Watch GT 5 | F29: Shopee | G29: =COUNT(Huawei_GT5!$F$5:$F$7) -> 3 | H29: =IF(G29=0,"",AVERAGE(Huawei_GT5!$F$5:$F$7)) -> 4686.6667 | I29: =IF(G29=0,"",MEDIAN(Huawei_GT5!$F$5:$F$7)) -> 4990 | J29: =IF(G29<2,"",STDEV(Huawei_GT5!$F$5:$F$7)) -> 525.38874 | K29: =IF(OR(G29<2,H29=0),"",J29/H29*100) -> 11.210286 | L29: =IF(G29=0,"",MIN(Huawei_GT5!$F$5:$F$7)) -> 4080 | M29: =IF(G29=0,"",QUARTILE(Huawei_GT5!$F$5:$F$7,1)) -> 4535 | N29: =IF(G29=0,"",QUARTILE(Huawei_GT5!$F$5:$F$7,3)) -> 4990 | O29: =IF(G29=0,"",MAX(Huawei_GT5!$F$5:$F$7)) -> 4990 | P29: =COUNT(Huawei_GT5!$G$5:$G$7) -> 3 | Q29: =IF(P29=0,"",AVERAGE(Huawei_GT5!$G$5:$G$7)) -> 4.9666667 | R29: =IF(P29=0,"",MEDIAN(Huawei_GT5!$G$5:$G$7)) -> 5 | S29: =IF(P29<2,"",STDEV(Huawei_GT5!$G$5:$G$7)) -> 0.057735027 | T29: =IF(OR(P29<2,Q29=0),"",S29/Q29*100) -> 1.1624502 | U29: =IF(P29=0,"",MIN(Huawei_GT5!$G$5:$G$7)) -> 4.9 | V29: =IF(P29=0,"",QUARTILE(Huawei_GT5!$G$5:$G$7,1)) -> 4.95 | W29: =IF(P29=0,"",QUARTILE(Huawei_GT5!$G$5:$G$7,3)) -> 5 | X29: =IF(P29=0,"",MAX(Huawei_GT5!$G$5:$G$7)) -> 5
B30: Model × Platform | C30: Premium Sport | D30: Apple | E30: Apple Watch Ultra 2 | F30: Lazada | G30: =0 -> 0 | P30: =0 -> 0
B31: Model × Platform | C31: Premium Sport | D31: Apple | E31: Apple Watch Ultra 2 | F31: Shopee | G31: =0 -> 0 | P31: =0 -> 0
B32: Model × Platform | C32: Premium Sport | D32: Samsung | E32: Galaxy Watch Ultra | F32: Lazada | G32: =COUNT(Galaxy_Ultra!$F$3:$F$21) -> 19 | H32: =IF(G32=0,"",AVERAGE(Galaxy_Ultra!$F$3:$F$21)) -> 18454.947 | I32: =IF(G32=0,"",MEDIAN(Galaxy_Ultra!$F$3:$F$21)) -> 17990 | J32: =IF(G32<2,"",STDEV(Galaxy_Ultra!$F$3:$F$21)) -> 6794.1033 | K32: =IF(OR(G32<2,H32=0),"",J32/H32*100) -> 36.814536 | L32: =IF(G32=0,"",MIN(Galaxy_Ultra!$F$3:$F$21)) -> 6500 | M32: =IF(G32=0,"",QUARTILE(Galaxy_Ultra!$F$3:$F$21,1)) -> 13935 | N32: =IF(G32=0,"",QUARTILE(Galaxy_Ultra!$F$3:$F$21,3)) -> 23370 | O32: =IF(G32=0,"",MAX(Galaxy_Ultra!$F$3:$F$21)) -> 29950 | P32: =COUNT(Galaxy_Ultra!$G$3:$G$21) -> 7 | Q32: =IF(P32=0,"",AVERAGE(Galaxy_Ultra!$G$3:$G$21)) -> 4.6428571 | R32: =IF(P32=0,"",MEDIAN(Galaxy_Ultra!$G$3:$G$21)) -> 5 | S32: =IF(P32<2,"",STDEV(Galaxy_Ultra!$G$3:$G$21)) -> 0.73904701 | T32: =IF(OR(P32<2,Q32=0),"",S32/Q32*100) -> 15.917936 | U32: =IF(P32=0,"",MIN(Galaxy_Ultra!$G$3:$G$21)) -> 3 | V32: =IF(P32=0,"",QUARTILE(Galaxy_Ultra!$G$3:$G$21,1)) -> 4.75 | W32: =IF(P32=0,"",QUARTILE(Galaxy_Ultra!$G$3:$G$21,3)) -> 5 | X32: =IF(P32=0,"",MAX(Galaxy_Ultra!$G$3:$G$21)) -> 5
B33: Model × Platform | C33: Premium Sport | D33: Samsung | E33: Galaxy Watch Ultra | F33: Shopee | G33: =COUNT(Galaxy_Ultra!$F$22:$F$34) -> 13 | H33: =IF(G33=0,"",AVERAGE(Galaxy_Ultra!$F$22:$F$34)) -> 19796.923 | I33: =IF(G33=0,"",MEDIAN(Galaxy_Ultra!$F$22:$F$34)) -> 17490 | J33: =IF(G33<2,"",STDEV(Galaxy_Ultra!$F$22:$F$34)) -> 6957.5286 | K33: =IF(OR(G33<2,H33=0),"",J33/H33*100) -> 35.144495 | L33: =IF(G33=0,"",MIN(Galaxy_Ultra!$F$22:$F$34)) -> 12990 | M33: =IF(G33=0,"",QUARTILE(Galaxy_Ultra!$F$22:$F$34,1)) -> 14405 | N33: =IF(G33=0,"",QUARTILE(Galaxy_Ultra!$F$22:$F$34,3)) -> 19920 | O33: =IF(G33=0,"",MAX(Galaxy_Ultra!$F$22:$F$34)) -> 34055 | P33: =COUNT(Galaxy_Ultra!$G$22:$G$34) -> 13 | Q33: =IF(P33=0,"",AVERAGE(Galaxy_Ultra!$G$22:$G$34)) -> 4.8923077 | R33: =IF(P33=0,"",MEDIAN(Galaxy_Ultra!$G$22:$G$34)) -> 5 | S33: =IF(P33<2,"",STDEV(Galaxy_Ultra!$G$22:$G$34)) -> 0.27221786 | T33: =IF(OR(P33<2,Q33=0),"",S33/Q33*100) -> 5.5642016 | U33: =IF(P33=0,"",MIN(Galaxy_Ultra!$G$22:$G$34)) -> 4 | V33: =IF(P33=0,"",QUARTILE(Galaxy_Ultra!$G$22:$G$34,1)) -> 4.9 | W33: =IF(P33=0,"",QUARTILE(Galaxy_Ultra!$G$22:$G$34,3)) -> 5 | X33: =IF(P33=0,"",MAX(Galaxy_Ultra!$G$22:$G$34)) -> 5
B34: Model × Platform | C34: Premium Sport | D34: Huawei | E34: Huawei Watch Ultimate | F34: Lazada | G34: =COUNT(Huawei_Ultimate!$F$3:$F$4) -> 2 | H34: =IF(G34=0,"",AVERAGE(Huawei_Ultimate!$F$3:$F$4)) -> 19400 | I34: =IF(G34=0,"",MEDIAN(Huawei_Ultimate!$F$3:$F$4)) -> 19400 | J34: =IF(G34<2,"",STDEV(Huawei_Ultimate!$F$3:$F$4)) -> 6363.961 | K34: =IF(OR(G34<2,H34=0),"",J34/H34*100) -> 32.803923 | L34: =IF(G34=0,"",MIN(Huawei_Ultimate!$F$3:$F$4)) -> 14900 | M34: =IF(G34=0,"",QUARTILE(Huawei_Ultimate!$F$3:$F$4,1)) -> 17150 | N34: =IF(G34=0,"",QUARTILE(Huawei_Ultimate!$F$3:$F$4,3)) -> 21650 | O34: =IF(G34=0,"",MAX(Huawei_Ultimate!$F$3:$F$4)) -> 23900 | P34: =COUNT(Huawei_Ultimate!$G$3:$G$4) -> 0 | Q34: =IF(P34=0,"",AVERAGE(Huawei_Ultimate!$G$3:$G$4)) | R34: =IF(P34=0,"",MEDIAN(Huawei_Ultimate!$G$3:$G$4)) | S34: =IF(P34<2,"",STDEV(Huawei_Ultimate!$G$3:$G$4)) | T34: =IF(OR(P34<2,Q34=0),"",S34/Q34*100) | U34: =IF(P34=0,"",MIN(Huawei_Ultimate!$G$3:$G$4)) | V34: =IF(P34=0,"",QUARTILE(Huawei_Ultimate!$G$3:$G$4,1)) | W34: =IF(P34=0,"",QUARTILE(Huawei_Ultimate!$G$3:$G$4,3)) | X34: =IF(P34=0,"",MAX(Huawei_Ultimate!$G$3:$G$4))
B35: Model × Platform | C35: Premium Sport | D35: Huawei | E35: Huawei Watch Ultimate | F35: Shopee | G35: =COUNT(Huawei_Ultimate!$F$5:$F$6) -> 2 | H35: =IF(G35=0,"",AVERAGE(Huawei_Ultimate!$F$5:$F$6)) -> 19900 | I35: =IF(G35=0,"",MEDIAN(Huawei_Ultimate!$F$5:$F$6)) -> 19900 | J35: =IF(G35<2,"",STDEV(Huawei_Ultimate!$F$5:$F$6)) -> 0 | K35: =IF(OR(G35<2,H35=0),"",J35/H35*100) -> 0 | L35: =IF(G35=0,"",MIN(Huawei_Ultimate!$F$5:$F$6)) -> 19900 | M35: =IF(G35=0,"",QUARTILE(Huawei_Ultimate!$F$5:$F$6,1)) -> 19900 | N35: =IF(G35=0,"",QUARTILE(Huawei_Ultimate!$F$5:$F$6,3)) -> 19900 | O35: =IF(G35=0,"",MAX(Huawei_Ultimate!$F$5:$F$6)) -> 19900 | P35: =COUNT(Huawei_Ultimate!$G$5:$G$6) -> 2 | Q35: =IF(P35=0,"",AVERAGE(Huawei_Ultimate!$G$5:$G$6)) -> 4.95 | R35: =IF(P35=0,"",MEDIAN(Huawei_Ultimate!$G$5:$G$6)) -> 4.95 | S35: =IF(P35<2,"",STDEV(Huawei_Ultimate!$G$5:$G$6)) -> 0.070710678 | T35: =IF(OR(P35<2,Q35=0),"",S35/Q35*100) -> 1.4284985 | U35: =IF(P35=0,"",MIN(Huawei_Ultimate!$G$5:$G$6)) -> 4.9 | V35: =IF(P35=0,"",QUARTILE(Huawei_Ultimate!$G$5:$G$6,1)) -> 4.925 | W35: =IF(P35=0,"",QUARTILE(Huawei_Ultimate!$G$5:$G$6,3)) -> 4.975 | X35: =IF(P35=0,"",MAX(Huawei_Ultimate!$G$5:$G$6)) -> 5

Sheet All_Data
B2: brand | C2: model | D2: platform | E2: product_name | F2: price | G2: rating
B3: Apple | C3: Apple Watch Series 10 | D3: Lazada | E3: Apple Watch Series 10(2024) GPS 42mm,46mm - Aluminium Case with Sport Loop | F3: 15900 | G3: 5
B4: Apple | C4: Apple Watch Series 10 | D4: Shopee | E4: Apple Watch Series 10 GPS + Cellular 42mm Titanium Case with Sport Band | F4: 18130 | G4: 4.8
B5: Apple | C5: Apple Watch Series 10 | D5: Shopee | E5: Apple Watch Series 10 GPS+Cellular Titanium Case สาย Milanese Loop I iStudio by SPVi | F5: 27200 | G5: 5
B6: Apple | C6: Apple Watch Series 9 | D6: Lazada | E6: Apple Watch Series 9 GPS+Cellular สาย Sport Loop I iStudio by SPVi | F6: 20900 | G6: 5
B7: Huawei | C7: Huawei Watch GT 4 | D7: Lazada | E7: HUAWEI WATCH GT 4 46mm /41mm สมาร์ทวอทช์ หลากสไตล์บนข้อมือด้วยหน้าจอ AMOLED ผู้ช่วยด้านสุขภาพ | F7: 9990
B8: Huawei | C8: Huawei Watch GT 4 | D8: Lazada | E8: Huawei WATCH GT 4 SmartWatch NFC Bluetooth Call HarmonyOS 4 | F8: 3990
B9: Huawei | C9: Huawei Watch GT 4 | D9: Lazada | E9: Huawei WATCH GT 4 SmartWatch NFC Bluetooth Call HarmonyOS 4 | F9: 3990 | G9: 5
B10: Huawei | C10: Huawei Watch GT 4 | D10: Lazada | E10: Huawei Watch Gt 4 41mm (Light Gold Edition) Genuine, Brand New, with 1 Year Warranty (Stock Item) | F10: 3990
B11: Huawei | C11: Huawei Watch GT 4 | D11: Shopee | E11: Huawei WATCH GT 4 SmartWatch NFC Bluetooth Call HarmonyOS 4 | F11: 3690 | G11: 5
B12: Huawei | C12: Huawei Watch GT 4 | D12: Shopee | E12: HUAWEI WATCH GT 4 41mm Silver สมาร์ทวอทช์ ตัวเรือนใหม่ไม่มีตำหนิ | F12: 6500 | G12: 4.9
B13: Huawei | C13: Huawei Watch GT 5 | D13: Lazada | E13: Huawei Watch Gt 5 46mm Smartwatch | Battery Life up to 2 Weeks | Measure Various Aspects of Health. | F13: 20980.7
B14: Huawei | C14: Huawei Watch GT 5 | D14: Lazada | E14: HUAWEI WATCH GT 5 | สมาร์ทวอชดีไซน์สวยฟังก์ชั่นครบ ใช้ได้ทั้ง iOSและAndroid | F14: 4990 | G14: 5
B15: Huawei | C15: Huawei Watch GT 5 | D15: Shopee | E15: HUAWEI WATCH GT 5 | สมาร์ทวอชดีไซน์สวยฟังก์ชั่นครบ ใช้ได้ทั้ง iOSและAndroid | F15: 4990 | G15: 4.9
B16: Huawei | C16: Huawei Watch GT 5 | D16: Shopee | E16: Huawei Watch GT5 (46") สินค้าเคลียสตอค ประกันร้าน | F16: 4080 | G16: 5
B17: Huawei | C17: Huawei Watch GT 5 | D17: Shopee | E17: HUAWEI WATCH GT 5 | สมาร์ทวอชดีไซน์สวยฟังก์ชั่นครบ ใช้ได้ทั้ง iOSและAndroid | F17: 4990 | G17: 5
B18: Huawei | C18: Huawei Watch Ultimate | D18: Lazada | E18: Huawei Watch Ultimate Expedition Black สมาร์ทวอทช์ 48 MM ประกันศูนย์ | F18: 23900
B19: Huawei | C19: Huawei Watch Ultimate | D19: Lazada | E19: Huawei Watch Ultimate (Blue) New Device (Non-Chinese Rom) Can Be Used Just Like a Normal Thai Device in Every Way. | F19: 14900
B20: Huawei | C20: Huawei Watch Ultimate | D20: Shopee | E20: HUAWEI WATCH ULTIMATE GREEN ตัวเรือนสวย อุปกรณ์ครบ | F20: 19900 | G20: 4.9
B21: Huawei | C21: Huawei Watch Ultimate | D21: Shopee | E21: Huawei WATCH Ultimate GREEN | F21: 19900 | G21: 5
B22: Samsung | C22: Galaxy Watch Ultra | D22: Lazada | E22: Samsung Galaxy Watch Ultra 2025 LTE 47mm สมาร์ทวอทช์พรีเมี่ยม Titanium จอ Sapphire AI Health GPS แท้ศูนย์ | F22: 28990
B23: Samsung | C23: Galaxy Watch Ultra | D23: Lazada | E23: Samsung Galaxy Watch Ultra 2025 ประกันศูนย์ Samsung 1ปี | F23: 17990
B24: Samsung | C24: Galaxy Watch Ultra | D24: Lazada | E24: Samsung Galaxy Watch Ultra 2025 LTE นาฬิกาอัจฉริยะ 47mm ดีไซน์ Titanium หน้าจอ Sapphire Crystal ฟีเจอร์สุขภาพ AI | F24: 29950
B25: Samsung | C25: Galaxy Watch Ultra | D25: Lazada | E25: Samsung Galaxy Watch Ultra LTE GY ประกันศูนย์ | F25: 23390
B26: Samsung | C26: Galaxy Watch Ultra | D26: Lazada | E26: Samsung Galaxy Watch Ultra 2025 LTE Titanium Blue โดย สยามทีวี by Siam T.V. | F26: 22410
B27: Samsung | C27: Galaxy Watch Ultra | D27: Lazada | E27: Samsung Galaxy Watch Ultra (LTE, 47mm) ประกันศูนย์ | F27: 23350
B28: Samsung | C28: Galaxy Watch Ultra | D28: Lazada | E28: สมาร์ทวอชท์ Samsung Galaxy Watch Ultra LTE 47mm สี Titanium Gray รุ่น LTE ประกันศูนย์ | F28: 23350
B29: Samsung | C29: Galaxy Watch Ultra | D29: Lazada | E29: Samsung Galaxy Watch Ultra (LTE, 47mm) ( รุ่น SS-AC-L705(TG) ) ประกันศูนย์ | F29: 23769
B30: Samsung | C30: Galaxy Watch Ultra | D30: Lazada | E30: Samsung Galaxy Watch Ultra (สินค้าเครื่องศูนย์ไทย ของแท้แน่นอน)(รับประกันร้าน) จัดส่งฟรี!!! | F30: 13980
B31: Samsung | C31: Galaxy Watch Ultra | D31: Lazada | E31: Samsung Galaxy Watch Ultra 2025 เครื่องศูนย์ไทย | F31: 14290
B32: Samsung | C32: Galaxy Watch Ultra | D32: Lazada | E32: Samsung Galaxy Watch Ultra ประกันศูนย์ Samsung 1ปี | F32: 15990
B33: Samsung | C33: Galaxy Watch Ultra | D33: Lazada | E33: Samsung Galaxy Watch Ultra (สินค้าของแท้แน่นอน100% เครื่องศูนย์ไทย) รับประกันร้าน 1 เดือน จัดส่งฟรี) | F33: 12980 | G33: 5
B34: Samsung | C34: Galaxy Watch Ultra | D34: Lazada | E34: Samsung Galaxy Watch Ultra 2025 เครื่องศูนย์ไทย | F34: 14290 | G34: 5
B35: Samsung | C35: Galaxy Watch Ultra | D35: Lazada | E35: SAMSUNG Galaxy Watch Ultra สมาร์ทวอช Amoled 1.5นิ้ว ไทเทเนี่ยม สำหรับ Andriod เท่านั้น ประกันศูนย์ | F35: 13890
B36: Samsung | C36: Galaxy Watch Ultra | D36: Lazada | E36: Samsung Galaxy Watch Ultra(2025) 64GB LTE | F36: 18790 | G36: 4.9
B37: Samsung | C37: Galaxy Watch Ultra | D37: Lazada | E37: Samsung Galaxy Watch Ultra (2025) (47mm) (สินค้ารับประกัน1ปี) By TG | F37: 26145 | G37: 4.6
B38: Samsung | C38: Galaxy Watch Ultra | D38: Lazada | E38: SAMSUNG Galaxy Watch Ultra สมาร์ทวอช Amoled 1.5นิ้ว ไทเทเนี่ยม สำหรับ Andriod เท่านั้น ประกันศูนย์ | F38: 6800 | G38: 5
B39: Samsung | C39: Galaxy Watch Ultra | D39: Lazada | E39: SAMSUNG Galaxy Watch Ultra สมาร์ทวอช Amoled 1.5นิ้ว ไทเทเนี่ยม สำหรับ Andriod เท่านั้น ประกันศูนย์ | F39: 6500 | G39: 3
B40: Samsung | C40: Galaxy Watch Ultra | D40: Lazada | E40: Samsung Galaxy Watch Ultra(2025) 64GB LTE | F40: 13790 | G40: 5
B41: Samsung | C41: Galaxy Watch Ultra | D41: Shopee | E41: Samsung Galaxy Watch Ultra (2025 Edition) 47mm LTE Smartwatch | F41: 14405 | G41: 5
...

Sheet Apple
B2: brand | C2: model | D2: platform | E2: product_name | F2: price | G2: rating
B3: Apple | C3: Apple Watch Series 10 | D3: Lazada | E3: Apple Watch Series 10(2024) GPS 42mm,46mm - Aluminium Case with Sport Loop | F3: 15900 | G3: 5
B4: Apple | C4: Apple Watch Series 10 | D4: Shopee | E4: Apple Watch Series 10 GPS + Cellular 42mm Titanium Case with Sport Band | F4: 18130 | G4: 4.8
B5: Apple | C5: Apple Watch Series 10 | D5: Shopee | E5: Apple Watch Series 10 GPS+Cellular Titanium Case สาย Milanese Loop I iStudio by SPVi | F5: 27200 | G5: 5
B6: Apple | C6: Apple Watch Series 9 | D6: Lazada | E6: Apple Watch Series 9 GPS+Cellular สาย Sport Loop I iStudio by SPVi | F6: 20900 | G6: 5

Sheet Samsung
B2: brand | C2: model | D2: platform | E2: product_name | F2: price | G2: rating
B3: Samsung | C3: Galaxy Watch Ultra | D3: Lazada | E3: SAMSUNG Galaxy Watch Ultra สมาร์ทวอช Amoled 1.5นิ้ว ไทเทเนี่ยม สำหรับ Andriod เท่านั้น ประกันศูนย์ | F3: 13890
B4: Samsung | C4: Galaxy Watch Ultra | D4: Lazada | E4: SAMSUNG Galaxy Watch Ultra สมาร์ทวอช Amoled 1.5นิ้ว ไทเทเนี่ยม สำหรับ Andriod เท่านั้น ประกันศูนย์ | F4: 6800 | G4: 5
B5: Samsung | C5: Galaxy Watch Ultra | D5: Lazada | E5: SAMSUNG Galaxy Watch Ultra สมาร์ทวอช Amoled 1.5นิ้ว ไทเทเนี่ยม สำหรับ Andriod เท่านั้น ประกันศูนย์ | F5: 6500 | G5: 3
B6: Samsung | C6: Galaxy Watch Ultra | D6: Lazada | E6: Samsung Galaxy Watch Ultra ประกันศูนย์ Samsung 1ปี | F6: 15990
B7: Samsung | C7: Galaxy Watch Ultra | D7: Lazada | E7: Samsung Galaxy Watch Ultra (2025) (47mm) (สินค้ารับประกัน1ปี) By TG | F7: 26145 | G7: 4.6
B8: Samsung | C8: Galaxy Watch Ultra | D8: Lazada | E8: Samsung Galaxy Watch Ultra (LTE, 47mm) ( รุ่น SS-AC-L705(TG) ) ประกันศูนย์ | F8: 23769
B9: Samsung | C9: Galaxy Watch Ultra | D9: Lazada | E9: Samsung Galaxy Watch Ultra (LTE, 47mm) ประกันศูนย์ | F9: 23350
B10: Samsung | C10: Galaxy Watch Ultra | D10: Lazada | E10: Samsung Galaxy Watch Ultra (สินค้าของแท้แน่นอน100% เครื่องศูนย์ไทย) รับประกันร้าน 1 เดือน จัดส่งฟรี) | F10: 12980 | G10: 5
B11: Samsung | C11: Galaxy Watch Ultra | D11: Lazada | E11: Samsung Galaxy Watch Ultra (สินค้าเครื่องศูนย์ไทย ของแท้แน่นอน)(รับประกันร้าน) จัดส่งฟรี!!! | F11: 13980
B12: Samsung | C12: Galaxy Watch Ultra | D12: Lazada | E12: Samsung Galaxy Watch Ultra 2025 LTE 47mm สมาร์ทวอทช์พรีเมี่ยม Titanium จอ Sapphire AI Health GPS แท้ศูนย์ | F12: 28990
B13: Samsung | C13: Galaxy Watch Ultra | D13: Lazada | E13: Samsung Galaxy Watch Ultra 2025 LTE Titanium Blue โดย สยามทีวี by Siam T.V. | F13: 22410
B14: Samsung | C14: Galaxy Watch Ultra | D14: Lazada | E14: Samsung Galaxy Watch Ultra 2025 LTE นาฬิกาอัจฉริยะ 47mm ดีไซน์ Titanium หน้าจอ Sapphire Crystal ฟีเจอร์สุขภาพ AI | F14: 29950
B15: Samsung | C15: Galaxy Watch Ultra | D15: Lazada | E15: Samsung Galaxy Watch Ultra 2025 ประกันศูนย์ Samsung 1ปี | F15: 17990
B16: Samsung | C16: Galaxy Watch Ultra | D16: Lazada | E16: Samsung Galaxy Watch Ultra 2025 เครื่องศูนย์ไทย | F16: 14290
B17: Samsung | C17: Galaxy Watch Ultra | D17: Lazada | E17: Samsung Galaxy Watch Ultra 2025 เครื่องศูนย์ไทย | F17: 14290 | G17: 5
B18: Samsung | C18: Galaxy Watch Ultra | D18: Lazada | E18: Samsung Galaxy Watch Ultra LTE GY ประกันศูนย์ | F18: 23390
B19: Samsung | C19: Galaxy Watch Ultra | D19: Lazada | E19: Samsung Galaxy Watch Ultra(2025) 64GB LTE | F19: 18790 | G19: 4.9
B20: Samsung | C20: Galaxy Watch Ultra | D20: Lazada | E20: Samsung Galaxy Watch Ultra(2025) 64GB LTE | F20: 13790 | G20: 5
B21: Samsung | C21: Galaxy Watch Ultra | D21: Lazada | E21: สมาร์ทวอชท์ Samsung Galaxy Watch Ultra LTE 47mm สี Titanium Gray รุ่น LTE ประกันศูนย์ | F21: 23350
B22: Samsung | C22: Galaxy Watch Ultra | D22: Shopee | E22: # Samsung Galaxy Watch Ultra-2025-64GB-LTE-ศูนย์ไทยใหม่มาก | F22: 13900 | G22: 4.9
B23: Samsung | C23: Galaxy Watch Ultra | D23: Shopee | E23: ***แท้ศูนย์ไทย ร่วมโค้ด 2025 Galaxy Watch Ultra LTE | F23: 16999 | G23: 5
B24: Samsung | C24: Galaxy Watch Ultra | D24: Shopee | E24: SAMSUNG GALAXY WATCH ULTRA TITANIUM | F24: 32790 | G24: 4.9
B25: Samsung | C25: Galaxy Watch Ultra | D25: Shopee | E25: Samsung Galaxy Watch Ultra (2024)(LTE, 47mm) Galaxy AI สมาร์ทวอทช์ ของใหม่ แท้จากศูนย์ รับประกันศูนย์ซัมซุง netplus | F25: 17880 | G25: 4.9
B26: Samsung | C26: Galaxy Watch Ultra | D26: Shopee | E26: Samsung Galaxy Watch Ultra (2025 Edition) 47mm LTE Smartwatch | F26: 14405 | G26: 5
B27: Samsung | C27: Galaxy Watch Ultra | D27: Shopee | E27: Samsung Galaxy Watch Ultra 2025 (สินค้ารับประกันศูนย์ 1ปี) | F27: 26399 | G27: 5
B28: Samsung | C28: Galaxy Watch Ultra | D28: Shopee | E28: Samsung Galaxy Watch Ultra 2025 LTE ***ประกันศูนย์ไทย 1 ปี*** | F28: 19920 | G28: 5
B29: Samsung | C29: Galaxy Watch Ultra | D29: Shopee | E29: Samsung Galaxy Watch Ultra 2025 LTE Titanium | F29: 19175 | G29: 5
B30: Samsung | C30: Galaxy Watch Ultra | D30: Shopee | E30: Samsung Galaxy Watch Ultra 2025 | Titanium Blue | Smartwatch Body Terminal | Samsung Genuine Domestic Regular Product | Released in 2025 | Felica compatible | 5ATM+IP68 | Bluetooth v5.3 | Dual GPS equipped | Calling function | Up to 60 hours of battery li | F30: 34055 | G30: 4.9
B31: Samsung | C31: Galaxy Watch Ultra | D31: Shopee | E31: Samsung Galaxy Watch Ultra 2025 ประกันศูนย์ Samsung 1ปี | F31: 17490 | G31: 5
B32: Samsung | C32: Galaxy Watch Ultra | D32: Shopee | E32: Samsung Galaxy Watch Ultra 2025 เครื่องศูนย์ไทย | F32: 14290 | G32: 5
B33: Samsung | C33: Galaxy Watch Ultra | D33: Shopee | E33: Samsung Galaxy watch Ultra | F33: 12990 | G33: 5
... B35: Samsung | C35: Galaxy Watch7 | D35: Lazada | E35: ***แท้ศูนย์ไทย ร่วมโค้ด Galaxy Watch 7 | F35: 6999 | G35: 5
B36: Samsung | C36: Galaxy Watch7 | D36: Lazada | E36: 2025 นาฬิกาสมาร์ทวอทช์ Samsung Galaxy Watch 7 GPS ติดตามสำหรับผู้ชายและผู้หญิง Amoled แสดงผลตลอดเวลา นาฬิกาวัดอุณหภูมิร่างกาย BT สนทนา นาฬิกาสมาร์ทวอทช์ ผ่านบลูทูธ | F36: 1159.17
B37: Samsung | C37: Galaxy Watch7 | D37: Lazada | E37: Galaxy Watch7 (40mm, BT) Smartwatch ประกันศูนย์ | F37: 10659
B38: Samsung | C38: Galaxy Watch7 | D38: Lazada | E38: Samsung Galaxy Watch7 40mm Green 📍ราคา 3,500 - 📍 | F38: 3500
B39: Samsung | C39: Galaxy Watch7 | D39: Lazada | E39: Samsung Galaxy Watch 7 AI ประกันศูนย์ Samsung 1ปี | F39: 7490 | G39: 5
B40: Samsung | C40: Galaxy Watch7 | D40: Lazada | E40: Samsung Galaxy Watch7 40mm | F40: 10900
B41: Samsung | C41: Galaxy Watch7 | D41: Lazada | E41: Samsung Galaxy Watch7 AI สมาร์ทวอทช์ ระบบบลูทูธ 40MM,44MM | F41: 4990 | G41: 5
B42: Samsung | C42: Galaxy Watch7 | D42: Lazada | E42: นาฬิกาอัจฉริยะ Galaxy Watch 7 รุ่นใหม่ ขนาด 44 มม. สำหรับผู้ชาย รองรับการผ่านบลูทูธ ตรวจสุขภาพ ฟิตเนส กีฬา วัดออกซิเจนในเลือด สมาร์ทวอทช์สำหรับผู้ชาย รองรับ Android และ IOS | F42: 1047.45
...

Sheet Huawei
B2: brand | C2: model | D2: platform | E2: product_name | F2: price | G2: rating
B3: Huawei | C3: Huawei Watch GT 4 | D3: Lazada | E3: HUAWEI WATCH GT 4 46mm /41mm สมาร์ทวอทช์ หลากสไตล์บนข้อมือด้วยหน้าจอ AMOLED ผู้ช่วยด้านสุขภาพ | F3: 9990
B4: Huawei | C4: Huawei Watch GT 4 | D4: Lazada | E4: Huawei WATCH GT 4 SmartWatch NFC Bluetooth Call HarmonyOS 4 | F4: 3990
B5: Huawei | C5: Huawei Watch GT 4 | D5: Lazada | E5: Huawei WATCH GT 4 SmartWatch NFC Bluetooth Call HarmonyOS 4 | F5: 3990 | G5: 5
B6: Huawei | C6: Huawei Watch GT 4 | D6: Lazada | E6: Huawei Watch Gt 4 41mm (Light Gold Edition) Genuine, Brand New, with 1 Year Warranty (Stock Item) | F6: 3990
B7: Huawei | C7: Huawei Watch GT 4 | D7: Shopee | E7: HUAWEI WATCH GT 4 41mm Silver สมาร์ทวอทช์ ตัวเรือนใหม่ไม่มีตำหนิ | F7: 6500 | G7: 4.9
B8: Huawei | C8: Huawei Watch GT 4 | D8: Shopee | E8: Huawei WATCH GT 4 SmartWatch NFC Bluetooth Call HarmonyOS 4 | F8: 3690 | G8: 5
B9: Huawei | C9: Huawei Watch GT 5 | D9: Lazada | E9: HUAWEI WATCH GT 5 | สมาร์ทวอชดีไซน์สวยฟังก์ชั่นครบ ใช้ได้ทั้ง iOSและAndroid | F9: 4990 | G9: 5
B10: Huawei | C10: Huawei Watch GT 5 | D10: Lazada | E10: Huawei Watch Gt 5 46mm Smartwatch | Battery Life up to 2 Weeks | Measure Various Aspects of Health. | F10: 20980.7
B11: Huawei | C11: Huawei Watch GT 5 | D11: Shopee | E11: HUAWEI WATCH GT 5 | สมาร์ทวอชดีไซน์สวยฟังก์ชั่นครบ ใช้ได้ทั้ง iOSและAndroid | F11: 4990 | G11: 4.9
B12: Huawei | C12: Huawei Watch GT 5 | D12: Shopee | E12: HUAWEI WATCH GT 5 | สมาร์ทวอชดีไซน์สวยฟังก์ชั่นครบ ใช้ได้ทั้ง iOSและAndroid | F12: 4990 | G12: 5
B13: Huawei | C13: Huawei Watch GT 5 | D13: Shopee | E13: Huawei Watch GT5 (46") สินค้าเคลียสตอค ประกันร้าน | F13: 4080 | G13: 5
B14: Huawei | C14: Huawei Watch Ultimate | D14: Lazada | E14: Huawei Watch Ultimate (Blue) New Device (Non-Chinese Rom) Can Be Used Just Like a Normal Thai Device in Every Way. | F14: 14900
B15: Huawei | C15: Huawei Watch Ultimate | D15: Lazada | E15: Huawei Watch Ultimate Expedition Black สมาร์ทวอทช์ 48 MM ประกันศูนย์ | F15: 23900
B16: Huawei | C16: Huawei Watch Ultimate | D16: Shopee | E16: HUAWEI WATCH ULTIMATE GREEN ตัวเรือนสวย อุปกรณ์ครบ | F16: 19900 | G16: 4.9
B17: Huawei | C17: Huawei Watch Ultimate | D17: Shopee | E17: Huawei WATCH Ultimate GREEN | F17: 19900 | G17: 5

Sheet Apple_S9
B2: brand | C2: model | D2: platform | E2: product_name | F2: price | G2: rating
B3: Apple | C3: Apple Watch Series 9 | D3: Lazada | E3: Apple Watch Series 9 GPS+Cellular สาย Sport Loop I iStudio by SPVi | F3: 20900 | G3: 5

Sheet Galaxy_Watch7
B2: brand | C2: model | D2: platform | E2: product_name | F2: price | G2: rating
B3: Samsung | C3: Galaxy Watch7 | D3: Lazada | E3: ***แท้ศูนย์ไทย ร่วมโค้ด Galaxy Watch 7 | F3: 6999 | G3: 5
B4: Samsung | C4: Galaxy Watch7 | D4: Lazada | E4: 2025 นาฬิกาสมาร์ทวอทช์ Samsung Galaxy Watch 7 GPS ติดตามสำหรับผู้ชายและผู้หญิง Amoled แสดงผลตลอดเวลา นาฬิกาวัดอุณหภูมิร่างกาย BT สนทนา นาฬิกาสมาร์ทวอทช์ ผ่านบลูทูธ | F4: 1159.17
B5: Samsung | C5: Galaxy Watch7 | D5: Lazada | E5: Galaxy Watch7 (40mm, BT) Smartwatch ประกันศูนย์ | F5: 10659
B6: Samsung | C6: Galaxy Watch7 | D6: Lazada | E6: Samsung Galaxy Watch7 40mm Green 📍ราคา 3,500 - 📍 | F6: 3500
B7: Samsung | C7: Galaxy Watch7 | D7: Lazada | E7: Samsung Galaxy Watch 7 AI ประกันศูนย์ Samsung 1ปี | F7: 7490 | G7: 5
B8: Samsung | C8: Galaxy Watch7 | D8: Lazada | E8: Samsung Galaxy Watch7 40mm | F8: 10900
B9: Samsung | C9: Galaxy Watch7 | D9: Lazada | E9: Samsung Galaxy Watch7 AI สมาร์ทวอทช์ ระบบบลูทูธ 40MM,44MM | F9: 4990 | G9: 5
B10: Samsung | C10: Galaxy Watch7 | D10: Lazada | E10: นาฬิกาอัจฉริยะ Galaxy Watch 7 รุ่นใหม่ ขนาด 44 มม. สำหรับผู้ชาย รองรับการผ่านบลูทูธ ตรวจสุขภาพ ฟิตเนส กีฬา วัดออกซิเจนในเลือด สมาร์ทวอทช์สำหรับผู้ชาย รองรับ Android และ IOS | F10: 1047.45
B11: Samsung | C11: Galaxy Watch7 | D11: Lazada | E11: นาฬิกาอัจฉริยะ Galaxy Watch 7 รุ่นใหม่ ขนาด 44 มม. สำหรับผู้ชาย รองรับการผ่านบลูทูธ ตรวจสุขภาพ ฟิตเนส กีฬา วัดออกซิเจนในเลือด สมาร์ทวอทช์สำหรับผู้ชาย รองรับ Android และ IOS | F11: 1045.21
B12: Samsung | C12: Galaxy Watch7 | D12: Lazada | E12: นาฬิกาอัจฉริยะ Galaxy Watch 7 ใหม่ ขนาด 44 มม. สำหรับผู้ชาย ผ่านบลูทูธ ตรวจสอบสุขภาพ ฟิตเนส กีฬา อัตราการเต้นของหัวใจ ออกซิเจนในเลือด สมาร์ทวอทช์ผู้ชาย Android IOS | F12: 579.21
B13: Samsung | C13: Galaxy Watch7 | D13: Lazada | E13: นาฬิกาอัจฉริยะ Galaxy Watch 7 ใหม่ ขนาด 44 มม. สำหรับผู้ชาย ผ่านบลูทูธ ตรวจสอบสุขภาพ ฟิตเนส กีฬา อัตราการเต้นของหัวใจ ออกซิเจนในเลือด สมาร์ทวอทช์ผู้ชาย Android IOS | F13: 566.35 | G13: 5
B14: Samsung | C14: Galaxy Watch7 | D14: Lazada | E14: สมาร์ทวอทช์ Samsung Galaxy Watch 7 รุ่นปี 2025 พร้อมระบบติดตาม GPS สำหรับผู้ชายและผู้หญิง หน้าจอ AMOLED เปิดตลอดเวลา วัดอุณหภูมิร่างกาย รองรับการสนทนาผ่านบลูทูธ | F14: 826.39
B15: Samsung | C15: Galaxy Watch7 | D15: Lazada | E15: สมาร์ทวอทช์ Samsung Galaxy Watch7 AI Bluetooth 40mm | F15: 5899
B16: Samsung | C16: Galaxy Watch7 | D16: Shopee | E16: Galaxy Watch 7 สมาร์ทวอทช์สีเงิน - โทรไร้สาย, โทรศัพท์บลูทูธ, หน้าปัดนาฬิกาปรับแต่งได้, สไตล์สปอร์ต | F16: 670 | G16: 5
B17: Samsung | C17: Galaxy Watch7 | D17: Shopee | E17: Galaxy Watch7 (40mm, BT) Smartwatch ประกันศูนย์ | F17: 10659 | G17: 4.9
B18: Samsung | C18: Galaxy Watch7 | D18: Shopee | E18: Galaxy Watch7 44mm | Green | Smartwatch Body Device | Samsung Genuine Domestic Regular Product | SM-L310NZGJXJP | F18: 20995 | G18: 4.9
B19: Samsung | C19: Galaxy Watch7 | D19: Shopee | E19: Galaxy Watch7 AI สมาร์ทวอทช์ ระบบบลูทูธ 40MM เครื่องไทย | F19: 6990 | G19: 5
B20: Samsung | C20: Galaxy Watch7 | D20: Shopee | E20: New-Samsung Galaxy Watch 7 40mm,44mm (LTE /BT )-ใหม่ | F20: 9180 | G20: 4.9
B21: Samsung | C21: Galaxy Watch7 | D21: Shopee | E21: Samsung Galaxy Watch 7 AI ประกันศูนย์ Samsung 1ปี | F21: 7990 | G21: 5
B22: Samsung | C22: Galaxy Watch7 | D22: Shopee | E22: Samsung Galaxy Watch 7 SM-L300 l L310 (WiFi) / L305 l L315 (WiFi + LTE) Smartwatch – BRAND NEW | F22: 9286 | G22: 4.8
B23: Samsung | C23: Galaxy Watch7 | D23: Shopee | E23: Samsung Galaxy Watch 7 ประกันศูนย์ Samsung 1ปี | F23: 7990 | G23: 5
B24: Samsung | C24: Galaxy Watch7 | D24: Shopee | E24: Samsung Galaxy Watch7 40mm สี Cream/ Green | F24: 10900 | G24: 4.9
B25: Samsung | C25: Galaxy Watch7 | D25: Shopee | E25: Samsung ของแท้) Galaxy Watch 7 40mm(L305) / 44mm(L315) (ใหม่) Smart Watch (LTE GPS Cellular)-New | F25: 11618 | G25: 5
B26: Samsung | C26: Galaxy Watch7 | D26: Shopee | E26: ใหม่ Galaxy Watch 7 สมาร์ทวอท์ช 44 มม.ผู้ชายบลูทูธโทรสุขภาพ Monitor ฟิตเนสกีฬา Heart Rate เลือดออกซิเจนผู้ชาย Smartwatch Andriod IOS | F26: 563 | G26: 4.4
B27: Samsung | C27: Galaxy Watch7 | D27: Shopee | E27: ❥ ใหม่galaxy Watch 7 Smartwatch GPS Track Men Amoledเสมอแสดงอุณหภูมิร่างกายนาฬิกาbt Call Smartw | F27: 1624
B28: Samsung | C28: Galaxy Watch7 | D28: Shopee | E28: 【NEW】2025 Galaxy Watch7 1.45" waterproof IP68 supports GPS NFC smartwatch Bluetooth fitness smartwatch sports fitness | F28: 429 | G28: 4

Sheet Huawei_GT4
B2: brand | C2: model | D2: platform | E2: product_name | F2: price | G2: rating
B3: Huawei | C3: Huawei Watch GT 4 | D3: Lazada | E3: HUAWEI WATCH GT 4 46mm /41mm สมาร์ทวอทช์ หลากสไตล์บนข้อมือด้วยหน้าจอ AMOLED ผู้ช่วยด้านสุขภาพ | F3: 9990
B4: Huawei | C4: Huawei Watch GT 4 | D4: Lazada | E4: Huawei WATCH GT 4 SmartWatch NFC Bluetooth Call HarmonyOS 4 | F4: 3990
B5: Huawei | C5: Huawei Watch GT 4 | D5: Lazada | E5: Huawei WATCH GT 4 SmartWatch NFC Bluetooth Call HarmonyOS 4 | F5: 3990 | G5: 5
B6: Huawei | C6: Huawei Watch GT 4 | D6: Lazada | E6: Huawei Watch Gt 4 41mm (Light Gold Edition) Genuine, Brand New, with 1 Year Warranty (Stock Item) | F6: 3990
B7: Huawei | C7: Huawei Watch GT 4 | D7: Shopee | E7: HUAWEI WATCH GT 4 41mm Silver สมาร์ทวอทช์ ตัวเรือนใหม่ไม่มีตำหนิ | F7: 6500 | G7: 4.9
B8: Huawei | C8: Huawei Watch GT 4 | D8: Shopee | E8: Huawei WATCH GT 4 SmartWatch NFC Bluetooth Call HarmonyOS 4 | F8: 3690 | G8: 5

Sheet Apple_S10
B2: brand | C2: model | D2: platform | E2: product_name | F2: price | G2: rating
B3: Apple | C3: Apple Watch Series 10 | D3: Lazada | E3: Apple Watch Series 10(2024) GPS 42mm,46mm - Aluminium Case with Sport Loop | F3: 15900 | G3: 5
B4: Apple | C4: Apple Watch Series 10 | D4: Shopee | E4: Apple Watch Series 10 GPS + Cellular 42mm Titanium Case with Sport Band | F4: 18130 | G4: 4.8
B5: Apple | C5: Apple Watch Series 10 | D5: Shopee | E5: Apple Watch Series 10 GPS+Cellular Titanium Case สาย Milanese Loop I iStudio by SPVi | F5: 27200 | G5: 5

Sheet Galaxy_Watch8
B2: brand | C2: model | D2: platform | E2: product_name | F2: price | G2: rating
B3: Samsung | C3: Galaxy Watch8 | D3: Lazada | E3: ***แท้ศูนย์ไทย ร่วมโค้ด Galaxy Watch 8 | F3: 9999 | G3: 5
B4: Samsung | C4: Galaxy Watch8 | D4: Lazada | E4: Samsung Galaxy Watch 8 (Bluetooth, 44 mm) สี Graphite รุ่น SM-L330NDAAASA | F4: 15619
B5: Samsung | C5: Galaxy Watch8 | D5: Lazada | E5: Samsung Galaxy Watch 8 BT 40mm สี Graphite สวมใส่สบายตลอด 24 ชั่วโมง พร้อมหน้าจอ AMOLED สว่างสู้แดด และฟีเจอร์ Galaxy AI | F5: 5990 | G5: 5
B6: Samsung | C6: Galaxy Watch8 | D6: Lazada | E6: Samsung Galaxy Watch 8 [40/44 mm] AI smart watch | F6: 7790
B7: Samsung | C7: Galaxy Watch8 | D7: Lazada | E7: Samsung Galaxy Watch 8 ประกันศูนย์ Samsung 1ปี | F7: 10990 | G7: 5
B8: Samsung | C8: Galaxy Watch8 | D8: Lazada | E8: Samsung Galaxy Watch8 (Bluetooth, 40 mm) สมาร์ทวอทช์ AI | F8: 11900 | G8: 5
B9: Samsung | C9: Galaxy Watch8 | D9: Lazada | E9: Samsung Galaxy Watch8 (Bluetooth, 44 mm) สมาร์ทวอทช์ AI | F9: 5500 | G9: 4.7
B10: Samsung | C10: Galaxy Watch8 | D10: Lazada | E10: Samsung Galaxy Watch8 40 mm Bluetooth Graphite โดย สยามทีวี by Siam T.V. | F10: 13090
B11: Samsung | C11: Galaxy Watch8 | D11: Lazada | E11: Samsung Galaxy Watch8 40 mm Bluetooth Silver โดย สยามทีวี by Siam T.V. | F11: 13090
B12: Samsung | C12: Galaxy Watch8 | D12: Lazada | E12: Samsung Galaxy Watch8 40,44mm BT | F12: 8130 | G12: 5
B13: Samsung | C13: Galaxy Watch8 | D13: Lazada | E13: Samsung Galaxy Watch8 40,44mm BT | F13: 6849 | G13: 5
B14: Samsung | C14: Galaxy Watch8 | D14: Lazada | E14: Samsung Galaxy Watch8 40,44mm BT ซัมซุง สมาร์ทวอทช์ สายยางสีเทา หน้าปัดวงกลม แสดงเวลาและวันที่ | F14: 5133
B15: Samsung | C15: Galaxy Watch8 | D15: Lazada | E15: Samsung Galaxy Watch8 44mm (BT) (สินค้ารับประกันศูนย์ 1ปี) | F15: 6900 | G15: 1
B16: Samsung | C16: Galaxy Watch8 | D16: Lazada | E16: Samsung Galaxy Watch8 BT 40/44mm | F16: 10000
B17: Samsung | C17: Galaxy Watch8 | D17: Lazada | E17: Samsung Galaxy Watch8 ซัมซุง สมาร์ทวอทช์ สายสีขาว หน้าจอ 44 มิลลิเมตร แสดงผลดอกไม้ | F17: 5820
B18: Samsung | C18: Galaxy Watch8 | D18: Lazada | E18: ซัมซุง Samsung Galaxy Watch8 นาฬิกาอัจฉริยะ สายยางสีเทา designed to fit comfortably on various wrist sizes. | F18: 5120
B19: Samsung | C19: Galaxy Watch8 | D19: Lazada | E19: สมาร์ทวอชท์ SAMSUNG Galaxy Watch 8 40mm ประกันศูนย์ | F19: 12119
B20: Samsung | C20: Galaxy Watch8 | D20: Lazada | E20: สมาร์ทวอชท์ Samsung Galaxy Watch8 (Bluetooth, 40 mm) ประกันศูนย์ | F20: 11819
B21: Samsung | C21: Galaxy Watch8 | D21: Lazada | E21: สมาร์ทวอทช์ Samsung Galaxy Watch 8 40mm (Bluetooth) ขนาด 1.3 นิ้ว Amoled แบต325mAh จอวัสดุพรีเมี่ยม | F21: 11900
B22: Samsung | C22: Galaxy Watch8 | D22: Lazada | E22: สมาร์ทวอทช์ Samsung Galaxy Watch 8 40mm (สินค้ารับประกัน1ปี) By TG | F22: 12495 | G22: 5
B23: Samsung | C23: Galaxy Watch8 | D23: Lazada | E23: สมาร์ทวอทช์ Samsung Galaxy Watch 8 44mm (Bluetooth) ขนาด 1.47 นิ้ว Amoled แบต435mAh จอวัสดุพรีเมี่ยม | F23: 13900
B24: Samsung | C24: Galaxy Watch8 | D24: Lazada | E24: สมาร์ทวอทช์ Samsung Galaxy Watch8 40mm (Bluetooth) เลือกสีได้ by Banana IT | F24: 12693 | G24: 5
B25: Samsung | C25: Galaxy Watch8 | D25: Lazada | E25: 💢Samsung Galaxy Watch 8💢AI smart watch ใหม่มือ1️⃣ ของแท้ศูนย์ไทย 💯% | F25: 6417.87
B26: Samsung | C26: Galaxy Watch8 | D26: Shopee | E26: ***แท้ศูนย์ไทย ร่วมโค้ด Galaxy Watch 8 | F26: 9999 | G26: 5
B27: Samsung | C27: Galaxy Watch8 | D27: Shopee | E27: Galaxy Watch 8 (40")(44") สินค้าของแท้ศูนย์ไทยแท้ ค้างสต็อก ประกันร้านเท่านั้น | F27: 6980 | G27: 5
B28: Samsung | C28: Galaxy Watch8 | D28: Shopee | E28: Samsung Galaxy Watch 8 (2025), Graphite, 40mm, สมาร์ทวอทช์บลูทูธ | F28: 15927
B29: Samsung | C29: Galaxy Watch8 | D29: Shopee | E29: Samsung Galaxy Watch 8 (Bluetooth, 44 mm) รุ่น SM-L330NDAAASA สี Graphite | F29: 16009 | G29: 4.9
B30: Samsung | C30: Galaxy Watch8 | D30: Shopee | E30: Samsung Galaxy Watch 8 (Bluetooth, 44 mm) สี Graphite รุ่น SM-L330NDAAASA | F30: 15459 | G30: 5
B31: Samsung | C31: Galaxy Watch8 | D31: Shopee | E31: Samsung Galaxy Watch 8 40mm, 44mm LTE (SM-L325)* | F31: 16703 | G31: 5
B32: Samsung | C32: Galaxy Watch8 | D32: Shopee | E32: Samsung Galaxy Watch 8 Bluetooth Smartwatch | F32: 10747 | G32: 5
B33: Samsung | C33: Galaxy Watch8 | D33: Shopee | E33: Samsung Galaxy Watch 8 Bluetooth Smartwatch (40/44mm) | F33: 8690 | G33: 4.9
B34: Samsung | C34: Galaxy Watch8 | D34: Shopee | E34: Samsung Galaxy Watch 8 Bluetooth Smartwatch (40/44mm) นาฬิกาสมาร์ทวอทช์ ของซัมซุง หน้าจอ 1.47“ ประกันศูนย์ 1ปี | F34: 8490 | G34: 5
B35: Samsung | C35: Galaxy Watch8 | D35: Shopee | E35: Samsung Galaxy Watch 8 [40/44 mm] AI smart watch | F35: 7790 | G35: 5
B36: Samsung | C36: Galaxy Watch8 | D36: Shopee | E36: Samsung Galaxy Watch 8 ประกันศูนย์ Samsung 1ปี | F36: 10590 | G36: 5
B37: Samsung | C37: Galaxy Watch8 | D37: Shopee | E37: Samsung Galaxy Watch8 (Bluetooth, 40 mm) สมาร์ทวอทช์ AI | F37: 10900 | G37: 5
B38: Samsung | C38: Galaxy Watch8 | D38: Shopee | E38: Samsung Galaxy Watch8 40mm (BT) (สินค้ารับประกันศูนย์ 1ปี) | F38: 12619 | G38: 5
B39: Samsung | C39: Galaxy Watch8 | D39: Shopee | E39: Samsung Galaxy Watch8 40mm Bluetooth | F39: 7900 | G39: 5
B40: Samsung | C40: Galaxy Watch8 | D40: Shopee | E40: Samsung Galaxy Watch8 สมาร์ทวอทช์ ระบบบลูทูธ 40mm | F40: 9520 | G40: 5

Sheet Huawei_GT5
B2: brand | C2: model | D2: platform | E2: product_name | F2: price | G2: rating
B3: Huawei | C3: Huawei Watch GT 5 | D3: Lazada | E3: HUAWEI WATCH GT 5 | สมาร์ทวอชดีไซน์สวยฟังก์ชั่นครบ ใช้ได้ทั้ง iOSและAndroid | F3: 4990 | G3: 5
B4: Huawei | C4: Huawei Watch GT 5 | D4: Lazada | E4: Huawei Watch Gt 5 46mm Smartwatch | Battery Life up to 2 Weeks | Measure Various Aspects of Health. | F4: 20980.7
B5: Huawei | C5: Huawei Watch GT 5 | D5: Shopee | E5: HUAWEI WATCH GT 5 | สมาร์ทวอชดีไซน์สวยฟังก์ชั่นครบ ใช้ได้ทั้ง iOSและAndroid | F5: 4990 | G5: 4.9
B6: Huawei | C6: Huawei Watch GT 5 | D6: Shopee | E6: HUAWEI WATCH GT 5 | สมาร์ทวอชดีไซน์สวยฟังก์ชั่นครบ ใช้ได้ทั้ง iOSและAndroid | F6: 4990 | G6: 5
B7: Huawei | C7: Huawei Watch GT 5 | D7: Shopee | E7: Huawei Watch GT5 (46") สินค้าเคลียสตอค ประกันร้าน | F7: 4080 | G7: 5

Sheet Apple_Ultra2
B2: brand | C2: model | D2: platform | E2: product_name | F2: price | G2: rating

Sheet Galaxy_Ultra
B2: brand | C2: model | D2: platform | E2: product_name | F2: price | G2: rating
B3: Samsung | C3: Galaxy Watch Ultra | D3: Lazada | E3: SAMSUNG Galaxy Watch Ultra สมาร์ทวอช Amoled 1.5นิ้ว ไทเทเนี่ยม สำหรับ Andriod เท่านั้น ประกันศูนย์ | F3: 13890
B4: Samsung | C4: Galaxy Watch Ultra | D4: Lazada | E4: SAMSUNG Galaxy Watch Ultra สมาร์ทวอช Amoled 1.5นิ้ว ไทเทเนี่ยม สำหรับ Andriod เท่านั้น ประกันศูนย์ | F4: 6800 | G4: 5
B5: Samsung | C5: Galaxy Watch Ultra | D5: Lazada | E5: SAMSUNG Galaxy Watch Ultra สมาร์ทวอช Amoled 1.5นิ้ว ไทเทเนี่ยม สำหรับ Andriod เท่านั้น ประกันศูนย์ | F5: 6500 | G5: 3
B6: Samsung | C6: Galaxy Watch Ultra | D6: Lazada | E6: Samsung Galaxy Watch Ultra ประกันศูนย์ Samsung 1ปี | F6: 15990
B7: Samsung | C7: Galaxy Watch Ultra | D7: Lazada | E7: Samsung Galaxy Watch Ultra (2025) (47mm) (สินค้ารับประกัน1ปี) By TG | F7: 26145 | G7: 4.6
B8: Samsung | C8: Galaxy Watch Ultra | D8: Lazada | E8: Samsung Galaxy Watch Ultra (LTE, 47mm) ( รุ่น SS-AC-L705(TG) ) ประกันศูนย์ | F8: 23769
B9: Samsung | C9: Galaxy Watch Ultra | D9: Lazada | E9: Samsung Galaxy Watch Ultra (LTE, 47mm) ประกันศูนย์ | F9: 23350
B10: Samsung | C10: Galaxy Watch Ultra | D10: Lazada | E10: Samsung Galaxy Watch Ultra (สินค้าของแท้แน่นอน100% เครื่องศูนย์ไทย) รับประกันร้าน 1 เดือน จัดส่งฟรี) | F10: 12980 | G10: 5
B11: Samsung | C11: Galaxy Watch Ultra | D11: Lazada | E11: Samsung Galaxy Watch Ultra (สินค้าเครื่องศูนย์ไทย ของแท้แน่นอน)(รับประกันร้าน) จัดส่งฟรี!!! | F11: 13980
B12: Samsung | C12: Galaxy Watch Ultra | D12: Lazada | E12: Samsung Galaxy Watch Ultra 2025 LTE 47mm สมาร์ทวอทช์พรีเมี่ยม Titanium จอ Sapphire AI Health GPS แท้ศูนย์ | F12: 28990
B13: Samsung | C13: Galaxy Watch Ultra | D13: Lazada | E13: Samsung Galaxy Watch Ultra 2025 LTE Titanium Blue โดย สยามทีวี by Siam T.V. | F13: 22410
